Workbook
Name avelarval: #REF!
Name data: #REF!

Sheet South_CPUE_2026
A1: Table X. Available abundance indices for South Atlantic in 2026.
A2: updated
B3: =+COUNT(B12:B75) -> 31 | D3: =+COUNT(D12:D75) -> 31 | F3: =+COUNT(F12:F75) -> 36 | H3: =+COUNT(H12:H75) -> 36 | J3: =+COUNT(J12:J75) -> 14 | L3: =+COUNT(L12:L75) -> 15 | N3: =+COUNT(N12:N75) -> 34 | P3: =+COUNT(P12:P75) -> 21 | R3: =+COUNT(R12:R75) -> 23 | T3: =+COUNT(T12:T75) -> 31
A4: series | B4: Joint LL | D4: BRA-URY LL_withVessel | F4: n_SPN LL | H4: w_SPN LL | J4: JPN LL1 | L4: JPN LL2 | N4: JPN LL3 | P4: ZAF LL | R4: CTP LL1 | T4: CTP LL2
A5: age range
A6: units of index | B6: count | D6: count | F6: count | H6: weight | J6: count | L6: count | N6: count | P6: weight | R6: count | T6: count
A7: area | B7: Satl | D7: west of SAtl | F7: SAtl | H7: SAtl | J7: SAtl | L7: SAtl | N7: SAtl | P7: east of SAtl
A8: method | B8: delta lognormal | D8: GLM-delta-lognormal | F8: GLM – Lognormal | H8: GLM – Lognormal | J8: GLMM (sdmTMB) | L8: GLMM (sdmTMB) | N8: GLMM (sdmTMB) | P8: GAMM- delta-lognormal | T8: delta lognormal
A9: time of the year | F9: all months | H9: all months | J9: all months | L9: all months | N9: all months | P9: all months
A10: source | B10: SCRS/2026/043 | D10: SCRS/2026/052 | F10: SCRS/2026/018 | H10: SCRS/2026/018 | J10: SCRS/2026/034 | L10: SCRS/2026/034 | N10: SCRS/2026/034 | P10: SCRS/2026/050 | R10: SCRS/2022/051 | T10: SCRS/2026/056
A11: Year | B11: Std. | C11: CV | D11: Std. | E11: CV | F11: Std. | G11: CV | H11: Std. | I11: CV | J11: Std. | K11: CV | L11: Std. | M11: CV | N11: Std. | O11: CV | P11: Std. | Q11: CV | R11: Std. | S11: CV | T11: Std. | U11: CV
A12: 1962 | J12: 2.5 | K12: 0.09
A13: 1963 | J13: 1.9 | K13: 0.12
A14: 1964 | J14: 1.7 | K14: 0.07
A15: 1965 | J15: 1.2 | K15: 0.07
A16: 1966 | J16: 0.91 | K16: 0.1
A17: 1967 | J17: 0.46 | K17: 0.07
A18: 1968 | J18: 0.8 | K18: 0.1 | R18: 0.32900989 | S18: 0.091082152
A19: =+A18+1 -> 1969 | J19: 0.86 | K19: 0.06 | R19: 0.26380077 | S19: 0.066517906
A20: =+A19+1 -> 1970 | J20: 0.81 | K20: 0.06 | R20: 0.27512696 | S20: 0.0640321
A21: =+A20+1 -> 1971 | J21: 0.54 | K21: 0.08 | R21: 0.32417798 | S21: 0.068732988
A22: =+A21+1 -> 1972 | J22: 0.44 | K22: 0.11 | R22: 0.24949572 | S22: 0.068458442
A23: =+A22+1 -> 1973 | J23: 0.61 | K23: 0.19 | R23: 0.26956262 | S23: 0.09107387
A24: =+A23+1 -> 1974 | J24: 0.63 | K24: 0.28 | R24: 0.24951919 | S24: 0.075164843
A25: =+A24+1 -> 1975 | J25: 0.62 | K25: 0.21 | R25: 0.21201619 | S25: 0.078718721
A26: =+A25+1 -> 1976 | L26: 0.66 | M26: 0.27 | R26: 0.11683259 | S26: 0.075932971
A27: =+A26+1 -> 1977 | L27: 0.79 | M27: 0.22 | R27: 0.12657646 | S27: 0.068159231
A28: =+A27+1 -> 1978 | L28: 0.69 | M28: 0.18 | R28: 0.14503671 | S28: 0.068119133
A29: =+A28+1 -> 1979 | L29: 0.8 | M29: 0.23 | R29: 0.19109822 | S29: 0.079214008
A30: =+A29+1 -> 1980 | L30: 0.8 | M30: 0.14 | R30: 0.19047168 | S30: 0.070038221
A31: =+A30+1 -> 1981 | L31: 0.77 | M31: 0.14 | R31: 0.20374611 | S31: 0.066576859
A32: =+A31+1 -> 1982 | L32: 0.88 | M32: 0.13 | R32: 0.17996659 | S32: 0.066675724
A33: =+A32+1 -> 1983 | L33: 0.76 | M33: 0.13 | R33: 0.17582462 | S33: 0.080338266
A34: =+A33+1 -> 1984 | L34: 1.1 | M34: 0.16 | R34: 0.20681564 | S34: 0.088079336
A35: =+A34+1 -> 1985 | L35: 1.5 | M35: 0.09 | R35: 0.15549286 | S35: 0.07743682
A36: =+A35+1 -> 1986 | L36: 1 | M36: 0.09 | R36: 0.14213072 | S36: 0.070361952
A37: =+A36+1 -> 1987 | L37: 1.5 | M37: 0.1 | R37: 0.16097631 | S37: 0.073649738
A38: =+A37+1 -> 1988 | L38: 1.3 | M38: 0.08 | R38: 0.18779184 | S38: 0.092280103
A39: =+A38+1 -> 1989 | F39: 9.6328 | G39: 0.06497 | H39: 516.604 | I39: 0.061881 | L39: 1.2 | M39: 0.09 | R39: 0.21338357 | S39: 0.093064833
A40: =+A39+1 -> 1990 | F40: 7.2861 | G40: 0.046691 | H40: 402.493 | I40: 0.044473 | L40: 1.3 | M40: 0.09 | R40: 0.18131009 | S40: 0.07659271
...

Sheet South_Figure
A2: mean_per | B2: =+AVERAGE(B6:B68) -> 6.4827311 | C2: =+AVERAGE(C6:C68) -> 1.0794839 | D2: =+AVERAGE(D6:D68) -> 8.6215167 | E2: =+AVERAGE(E6:E68) -> 429.04511 | F2: =+AVERAGE(F6:F68) -> 0.99857143 | G2: =+AVERAGE(G6:G68) -> 1.0033333 | H2: =+AVERAGE(H6:H68) -> 1.0044118 | I2: =+AVERAGE(I6:I68) -> 1.0414286 | ... M2: =+AVERAGE(M6:M68) -> 0.24563786 | P2: scaled to mean
B3: =+COUNT(B6:B68) -> 31 | C3: =+COUNT(C6:C68) -> 31 | D3: =+COUNT(D6:D68) -> 36 | E3: =+COUNT(E6:E68) -> 36 | F3: =+COUNT(F6:F68) -> 14 | G3: =+COUNT(G6:G68) -> 15 | H3: =+COUNT(H6:H68) -> 34 | I3: =+COUNT(I6:I68) -> 21 | ... M3: =+COUNT(M6:M68) -> 31 | Q3: =+COUNT(Q6:Q68)-C3 -> 0 | R3: =+COUNT(R6:R68)-D3 -> 0 | S3: =+COUNT(S6:S68)-E3 -> 0 | T3: =+COUNT(T6:T68)-F3 -> 0 | U3: =+COUNT(U6:U68)-G3 -> 0 | V3: =+COUNT(V6:V68)-H3 -> 0 | W3: =+COUNT(W6:W68)-I3 -> 0 | X3: =+COUNT(X6:X68)-J3 -> 0 | ... AA3: =+COUNT(AA6:AA68)-M3 -> 0
B4: =+South_CPUE_2026!B3 -> 31 | C4: =+South_CPUE_2026!D3 -> 31 | D4: =+South_CPUE_2026!F3 -> 36 | E4: =+South_CPUE_2026!H3 -> 36 | F4: =+South_CPUE_2026!J3 -> 14 | G4: =+South_CPUE_2026!L3 -> 15 | H4: =+South_CPUE_2026!N3 -> 34 | I4: =+South_CPUE_2026!P3 -> 21 | J4: =+original!AO3 -> 31 | K4: =+original!AQ3 -> 12 | L4: =+South_CPUE_2026!R3 -> 23 | M4: =+South_CPUE_2026!T3 -> 31
A5: Year | B5: =+South_CPUE_2026!B4 -> Joint LL | C5: =+South_CPUE_2026!D4 -> BRA-URY LL_withVessel | D5: =+South_CPUE_2026!F4 -> n_SPN LL | E5: =+South_CPUE_2026!H4 -> w_SPN LL | F5: =+South_CPUE_2026!J4 -> JPN LL1 | G5: =+South_CPUE_2026!L4 -> JPN LL2 | H5: =+South_CPUE_2026!N4 -> JPN LL3 | I5: =+South_CPUE_2026!P4 -> ZAF LL | J5: =+original!AO4 -> URY LL hist* | K5: =+original!AQ4 -> URY LL* | L5: =+South_CPUE_2026!R4 -> CTP LL1 | M5: =+South_CPUE_2026!T4 -> CTP LL2 | P5: =+B5 -> Joint LL | Q5: =+C5 -> BRA-URY LL_withVessel | R5: =+D5 -> n_SPN LL | S5: =+E5 -> w_SPN LL | T5: =+F5 -> JPN LL1 | U5: =+G5 -> JPN LL2 | V5: =+H5 -> JPN LL3 | W5: =+I5 -> ZAF LL | ... AA5: =+M5 -> CTP LL2
A6: =+South_CPUE_2026!A12 -> 1962 | F6: =+South_CPUE_2026!J12 -> 2.5 | O6: =+A6 -> 1962 | T6: =+F6/F$2 -> 2.5035765
A7: =+South_CPUE_2026!A13 -> 1963 | F7: =+South_CPUE_2026!J13 -> 1.9 | O7: =+A7 -> 1963 | T7: =+F7/F$2 -> 1.9027182
A8: =+South_CPUE_2026!A14 -> 1964 | F8: =+South_CPUE_2026!J14 -> 1.7 | O8: =+A8 -> 1964 | T8: =+F8/F$2 -> 1.702432
A9: =+South_CPUE_2026!A15 -> 1965 | F9: =+South_CPUE_2026!J15 -> 1.2 | O9: =+A9 -> 1965 | T9: =+F9/F$2 -> 1.2017167
A10: =+South_CPUE_2026!A16 -> 1966 | F10: =+South_CPUE_2026!J16 -> 0.91 | O10: =+A10 -> 1966 | T10: =+F10/F$2 -> 0.91130186
A11: =+South_CPUE_2026!A17 -> 1967 | F11: =+South_CPUE_2026!J17 -> 0.46 | O11: =+A11 -> 1967 | T11: =+F11/F$2 -> 0.46065808
A12: =+South_CPUE_2026!A18 -> 1968 | F12: =+South_CPUE_2026!J18 -> 0.8 | L12: =+South_CPUE_2026!R18 -> 0.32900989 | O12: =+A12 -> 1968 | T12: =+F12/F$2 -> 0.80114449 | Z12: =+L12/L$2 -> 1.5930457
A13: =+South_CPUE_2026!A19 -> 1969 | F13: =+South_CPUE_2026!J19 -> 0.86 | L13: =+South_CPUE_2026!R19 -> 0.26380077 | O13: =+A13 -> 1969 | T13: =+F13/F$2 -> 0.86123033 | Z13: =+L13/L$2 -> 1.2773072
A14: =+South_CPUE_2026!A20 -> 1970 | F14: =+South_CPUE_2026!J20 -> 0.81 | L14: =+South_CPUE_2026!R20 -> 0.27512696 | O14: =+A14 -> 1970 | T14: =+F14/F$2 -> 0.8111588 | Z14: =+L14/L$2 -> 1.3321479
A15: =+South_CPUE_2026!A21 -> 1971 | F15: =+South_CPUE_2026!J21 -> 0.54 | L15: =+South_CPUE_2026!R21 -> 0.32417798 | O15: =+A15 -> 1971 | T15: =+F15/F$2 -> 0.54077253 | Z15: =+L15/L$2 -> 1.5696499
A16: =+South_CPUE_2026!A22 -> 1972 | F16: =+South_CPUE_2026!J22 -> 0.44 | L16: =+South_CPUE_2026!R22 -> 0.24949572 | O16: =+A16 -> 1972 | T16: =+F16/F$2 -> 0.44062947 | Z16: =+L16/L$2 -> 1.208043
A17: =+South_CPUE_2026!A23 -> 1973 | F17: =+South_CPUE_2026!J23 -> 0.61 | L17: =+South_CPUE_2026!R23 -> 0.26956262 | O17: =+A17 -> 1973 | T17: =+F17/F$2 -> 0.61087268 | Z17: =+L17/L$2 -> 1.3052057
A18: =+South_CPUE_2026!A24 -> 1974 | F18: =+South_CPUE_2026!J24 -> 0.63 | L18: =+South_CPUE_2026!R24 -> 0.24951919 | O18: =+A18 -> 1974 | T18: =+F18/F$2 -> 0.63090129 | Z18: =+L18/L$2 -> 1.2081566
A19: =+South_CPUE_2026!A25 -> 1975 | F19: =+South_CPUE_2026!J25 -> 0.62 | L19: =+South_CPUE_2026!R25 -> 0.21201619 | O19: =+A19 -> 1975 | T19: =+F19/F$2 -> 0.62088698 | Z19: =+L19/L$2 -> 1.0265694
A20: =+South_CPUE_2026!A26 -> 1976 | G20: =+South_CPUE_2026!L26 -> 0.66 | L20: =+South_CPUE_2026!R26 -> 0.11683259 | O20: =+A20 -> 1976 | U20: =+G20/G$2 -> 0.65780731 | Z20: =+L20/L$2 -> 0.56569624
A21: =+South_CPUE_2026!A27 -> 1977 | G21: =+South_CPUE_2026!L27 -> 0.79 | L21: =+South_CPUE_2026!R27 -> 0.12657646 | O21: =+A21 -> 1977 | U21: =+G21/G$2 -> 0.78737542 | Z21: =+L21/L$2 -> 0.61287547 | AJ21: joint index | AK21: 1994-2024
A22: =+South_CPUE_2026!A28 -> 1978 | G22: =+South_CPUE_2026!L28 -> 0.69 | L22: =+South_CPUE_2026!R28 -> 0.14503671 | O22: =+A22 -> 1978 | U22: =+G22/G$2 -> 0.68770764 | Z22: =+L22/L$2 -> 0.70225886 | AJ22: SPNLL (weight) | AK22: 1990-2024
A23: =+South_CPUE_2026!A29 -> 1979 | G23: =+South_CPUE_2026!L29 -> 0.8 | L23: =+South_CPUE_2026!R29 -> 0.19109822 | O23: =+A23 -> 1979 | U23: =+G23/G$2 -> 0.79734219 | Z23: =+L23/L$2 -> 0.92528586 | AJ23: JPNLL3 | AK23: 1990-2024
A24: =+South_CPUE_2026!A30 -> 1980 | G24: =+South_CPUE_2026!L30 -> 0.8 | L24: =+South_CPUE_2026!R30 -> 0.19047168 | O24: =+A24 -> 1980 | U24: =+G24/G$2 -> 0.79734219 | Z24: =+L24/L$2 -> 0.92225222 | AJ24: JPNLL2 | AK24: 1976-1989
A25: =+South_CPUE_2026!A31 -> 1981 | G25: =+South_CPUE_2026!L31 -> 0.77 | L25: =+South_CPUE_2026!R31 -> 0.20374611 | O25: =+A25 -> 1981 | U25: =+G25/G$2 -> 0.76744186 | Z25: =+L25/L$2 -> 0.98652617 | AJ25: JPNLL1 | AK25: use
A26: =+South_CPUE_2026!A32 -> 1982 | G26: =+South_CPUE_2026!L32 -> 0.88 | J26: =+original!AO34 -> 736 | L26: =+South_CPUE_2026!R32 -> 0.17996659 | O26: =+A26 -> 1982 | U26: =+G26/G$2 -> 0.87707641 | X26: =+J26/J$2 -> 2.4295602 | Z26: =+L26/L$2 -> 0.87138721 | AJ26: CTPLL1 | AK26: use
A27: =+South_CPUE_2026!A33 -> 1983 | G27: =+South_CPUE_2026!L33 -> 0.76 | J27: =+original!AO35 -> 407 | L27: =+South_CPUE_2026!R33 -> 0.17582462 | O27: =+A27 -> 1983 | U27: =+G27/G$2 -> 0.75747508 | X27: =+J27/J$2 -> 1.3435204 | Z27: =+L27/L$2 -> 0.85133205
A28: =+South_CPUE_2026!A34 -> 1984 | G28: =+South_CPUE_2026!L34 -> 1.1 | J28: =+original!AO36 -> 283 | L28: =+South_CPUE_2026!R34 -> 0.20681564 | O28: =+A28 -> 1984 | U28: =+G28/G$2 -> 1.0963455 | X28: =+J28/J$2 -> 0.93419231 | Z28: =+L28/L$2 -> 1.0013887
A29: =+South_CPUE_2026!A35 -> 1985 | G29: =+South_CPUE_2026!L35 -> 1.5 | J29: =+original!AO37 -> 155 | L29: =+South_CPUE_2026!R35 -> 0.15549286 | O29: =+A29 -> 1985 | U29: =+G29/G$2 -> 1.4950166 | X29: =+J29/J$2 -> 0.5116601 | Z29: =+L29/L$2 -> 0.75288691
A30: =+South_CPUE_2026!A36 -> 1986 | G30: =+South_CPUE_2026!L36 -> 1 | J30: =+original!AO38 -> 189 | L30: =+South_CPUE_2026!R36 -> 0.14213072 | O30: =+A30 -> 1986 | U30: =+G30/G$2 -> 0.99667774 | X30: =+J30/J$2 -> 0.62389522 | Z30: =+L30/L$2 -> 0.68818823
A31: =+South_CPUE_2026!A37 -> 1987 | G31: =+South_CPUE_2026!L37 -> 1.5 | J31: =+original!AO39 -> 386 | L31: =+South_CPUE_2026!R37 -> 0.16097631 | O31: =+A31 -> 1987 | U31: =+G31/G$2 -> 1.4950166 | X31: =+J31/J$2 -> 1.2741987 | Z31: =+L31/L$2 -> 0.77943744
A32: =+South_CPUE_2026!A38 -> 1988 | G32: =+South_CPUE_2026!L38 -> 1.3 | J32: =+original!AO40 -> 272 | L32: =+South_CPUE_2026!R38 -> 0.18779184 | O32: =+A32 -> 1988 | U32: =+G32/G$2 -> 1.2956811 | X32: =+J32/J$2 -> 0.89788095 | Z32: =+L32/L$2 -> 0.90927657
A33: =+South_CPUE_2026!A39 -> 1989 | D33: =+South_CPUE_2026!F39 -> 9.6328 | E33: =+South_CPUE_2026!H39 -> 516.604 | G33: =+South_CPUE_2026!L39 -> 1.2 | J33: =+original!AO41 -> 347 | L33: =+South_CPUE_2026!R39 -> 0.21338357 | O33: =+A33 -> 1989 | R33: =+D33/D$2 -> 1.1172976 | S33: =+E33/E$2 -> 1.2040785 | U33: =+G33/G$2 -> 1.1960133 | X33: =+J33/J$2 -> 1.1454584 | Z33: =+L33/L$2 -> 1.0331902
A34: =+South_CPUE_2026!A40 -> 1990 | D34: =+South_CPUE_2026!F40 -> 7.2861 | E34: =+South_CPUE_2026!H40 -> 402.493 | G34: =+South_CPUE_2026!L40 -> 1.3 | J34: =+original!AO42 -> 270 | L34: =+South_CPUE_2026!R40 -> 0.18131009 | O34: =+A34 -> 1990 | R34: =+D34/D$2 -> 0.84510653 | S34: =+E34/E$2 -> 0.93811347 | U34: =+G34/G$2 -> 1.2956811 | X34: =+J34/J$2 -> 0.89127888 | Z34: =+L34/L$2 -> 0.87789236
A35: =+South_CPUE_2026!A41 -> 1991 | D35: =+South_CPUE_2026!F41 -> 7.4092 | E35: =+South_CPUE_2026!H41 -> 394.518 | H35: =+South_CPUE_2026!N41 -> 2 | J35: =+original!AO43 -> 270 | O35: =+A35 -> 1991 | R35: =+D35/D$2 -> 0.85938476 | S35: =+E35/E$2 -> 0.91952569 | V35: =+H35/H$2 -> 1.9912152 | X35: =+J35/J$2 -> 0.89127888
A36: =+South_CPUE_2026!A42 -> 1992 | D36: =+South_CPUE_2026!F42 -> 6.6774 | E36: =+South_CPUE_2026!H42 -> 358.515 | H36: =+South_CPUE_2026!N42 -> 2.1 | J36: =+original!AO44 -> 189 | O36: =+A36 -> 1992 | R36: =+D36/D$2 -> 0.7745041 | S36: =+E36/E$2 -> 0.83561143 | V36: =+H36/H$2 -> 2.090776 | X36: =+J36/J$2 -> 0.62389522
A37: =+South_CPUE_2026!A43 -> 1993 | D37: =+South_CPUE_2026!F43 -> 6.0407 | E37: =+South_CPUE_2026!H43 -> 311.089 | H37: =+South_CPUE_2026!N43 -> 1.5 | J37: =+original!AO45 -> 463 | O37: =+A37 -> 1993 | R37: =+D37/D$2 -> 0.70065398 | S37: =+E37/E$2 -> 0.72507294 | V37: =+H37/H$2 -> 1.4934114 | X37: =+J37/J$2 -> 1.5283782
A38: =+South_CPUE_2026!A44 -> 1994 | B38: =+South_CPUE_2026!B44 -> 9.320395 | C38: =+South_CPUE_2026!D44 -> 0.915 | D38: =+South_CPUE_2026!F44 -> 7.3698 | E38: =+South_CPUE_2026!H44 -> 359.152 | H38: =+South_CPUE_2026!N44 -> 1.6 | J38: =+original!AO46 -> 334 | M38: =+South_CPUE_2026!T44 -> 0.58632003 | O38: =+A38 -> 1994 | P38: =+B38/B$2 -> 1.4377266 | Q38: =+C38/C$2 -> 0.8476273 | R38: =+D38/D$2 -> 0.85481479 | S38: =+E38/E$2 -> 0.83709613 | V38: =+H38/H$2 -> 1.5929722 | X38: =+J38/J$2 -> 1.102545 | AA38: =+M38/M$2 -> 2.3869285
A39: =+South_CPUE_2026!A45 -> 1995 | B39: =+South_CPUE_2026!B45 -> 8.220347 | C39: =+South_CPUE_2026!D45 -> 1.262 | D39: =+South_CPUE_2026!F45 -> 8.6717 | E39: =+South_CPUE_2026!H45 -> 410.605 | H39: =+South_CPUE_2026!N45 -> 1.2 | J39: =+original!AO47 -> 500 | M39: =+South_CPUE_2026!T45 -> 0.39702097 | O39: =+A39 -> 1995 | P39: =+B39/B$2 -> 1.2680376 | Q39: =+C39/C$2 -> 1.1690772 | R39: =+D39/D$2 -> 1.0058207 | S39: =+E39/E$2 -> 0.95702058 | V39: =+H39/H$2 -> 1.1947291 | X39: =+J39/J$2 -> 1.6505165 | AA39: =+M39/M$2 -> 1.6162857
A40: =+South_CPUE_2026!A46 -> 1996 | B40: =+South_CPUE_2026!B46 -> 8.762103 | C40: =+South_CPUE_2026!D46 -> 1.216 | D40: =+South_CPUE_2026!F46 -> 7.5809 | E40: =+South_CPUE_2026!H46 -> 365.611 | H40: =+South_CPUE_2026!N46 -> 1.2 | J40: =+original!AO48 -> 416 | M40: =+South_CPUE_2026!T46 -> 0.43723129 | O40: =+A40 -> 1996 | P40: =+B40/B$2 -> 1.3516067 | Q40: =+C40/C$2 -> 1.1264643 | R40: =+D40/D$2 -> 0.87930005 | S40: =+E40/E$2 -> 0.85215049 | V40: =+H40/H$2 -> 1.1947291 | X40: =+J40/J$2 -> 1.3732297 | AA40: =+M40/M$2 -> 1.7799833
A41: =+South_CPUE_2026!A47 -> 1997 | B41: =+South_CPUE_2026!B47 -> 7.366469 | C41: =+South_CPUE_2026!D47 -> 1.191 | D41: =+South_CPUE_2026!F47 -> 7.6168 | E41: =+South_CPUE_2026!H47 -> 360.356 | H41: =+South_CPUE_2026!N47 -> 1.3 | J41: =+original!AO49 -> 452 | M41: =+South_CPUE_2026!T47 -> 0.27092018 | O41: =+A41 -> 1997 | P41: =+B41/B$2 -> 1.1363218 | Q41: =+C41/C$2 -> 1.103305 | R41: =+D41/D$2 -> 0.88346405 | S41: =+E41/E$2 -> 0.83990236 | V41: =+H41/H$2 -> 1.2942899 | X41: =+J41/J$2 -> 1.4920669 | AA41: =+M41/M$2 -> 1.1029252
...

Sheet South_Eval2026
A1: SWODP 2026 | C1: 2026 | K1: to joint BRA-URY LL | L1: to joint BRA-URY LL | M1: to joint BRA-URY LL
A2: need to update, contents are from 2022 | D2: 1994-2024
B3: Table for evaluating CPUE series for [stock] | C3: note: | E3: with/without Vessel | K3: Question to the Group: Do we need to keep these?
C4: unit | D4: number | E4: number | F4: weight/number | G4: number | H4: weight | I4: number | K4: weight | L4: weight | M4: weight
C5: Stock | D5: South | E5: South | F5: South | G5: South | H5: South | I5: South | K5: South | L5: South | M5: South
C6: Will be used in current stock assessment? State model/s. | D6: Yes | E6: Yes | F6: Yes | G6: Yes | H6: Yes | I6: Yes
C7: SCRS Doc No: | D7: SCRS/2026/043 | E7: SCRS/2026/052 | F7: SCRS/2026/018 | G7: SCRS/2026/034 | H7: SCRS/2026/050 | I7: SCRS/2026/056 | K7: SCRS/2017/078 | L7: SCRS/2013/101 | M7: SCRS/2022/057
C8: Index Name: | D8: joint LL | E8: BRA-URY LL | F8: SPN LL | G8: JPN LL | H8: ZAF LL | I8: CTP LL | K8: URY LL | L8: URY LL hist | M8: BRA LL
A9: Answer options | B9: 0 | C9: Data Source (state if based on logbooks, observer data etc.): | D9: Logbooks Observer | E9: Logbooks | F9: Voluntary scientific reporting fleet, observer data | G9: Logbooks | H9: Logbooks | I9: Logbooks | K9: Observer Program | L9: Logbooks | M9: Logbooks
A10: Retained only; Both | C10: Does the index include discarded and retained fish? | D10: Retained only | E10: Retained Only | F10: Retained only | G10: Retained Only | H10: Retained Only | I10: Retained only | K10: Both | L10: Retained Only | M10: Retained Only
A11: Yes/No/NA | B11: 1 | C11: Do the authors indicate the percentage of total effort of the fleet the CPUE data represents? | D11: Yes | E11: Yes | F11: Yes | G11: Yes | H11: Yes | I11: Yes | K11: No | L11: Yes | M11: Yes
A12: 0-10/11-20/21-30/31-40/41-50/51-60/61-70/71-80/81-90/91-100 | B12: 2 | C12: If the answer to 1 is yes, what is the percentage? | D12: 91-100% | E12: 71-80% | F12: 91-100% | G12: 91-100% | H12: 91-100% | I12: 91-100% | L12: 91-100% | M12: 71-80%
A13: Sufficient/Incomplete/None | B13: 3 | C13: Are sufficient diagnostics provided to assess model performance? | D13: Sufficient | E13: Sufficient | F13: Sufficient | G13: Sufficient | H13: Sufficient | I13: Sufficient | K13: Sufficient | L13: Sufficient | M13: Sufficient
A14: Well/Mixed/Poorly | B14: 4 | C14: How does the model perform relative to the diagnostics | D14: Well | E14: Well | F14: Well | G14: Well | H14: Well | I14: Well | K14: Well | L14: Well | M14: Well
A15: Yes/No/NA | B15: 5 | C15: Documented data exclusions and classifications? | D15: NA | E15: Yes | F15: NA | G15: Yes | H15: Yes | I15: NA | K15: Yes | L15: Yes | M15: Yes
A16: Yes/No/NA | B16: 6 | C16: Data exclusions appropriate? | D16: NA | E16: Yes | F16: NA | G16: Yes | H16: Yes | I16: NA | K16: Yes | L16: Yes | M16: Yes
A17: Yes/No/NA | B17: 7 | C17: Data classifications appropriate? | D17: NA | E17: Yes | F17: Yes | G17: Yes | H17: Yes | I17: NA | K17: Yes | L17: Yes | M17: Yes
A18: Atlantic/Atl N/Atl S/Atl NW/Atl NE/Atl SW/Atl SE/Tropical/Med/Localised(<10x10) | B18: 8 | C18: Geographical Area | D18: Atl S | E18: Atl SW | F18: Atl S | G18: Atl S | H18: Atl SE | I18: Atl S | K18: Atl SW | L18: Atl SW | M18: Atl SW
A19: Set/Trip/OTH | B19: 9 | C19: Data resolution level | D19: Set | E19: Set | F19: trip | G19: Set | H19: Set | I19: Set | K19: Set | L19: Set | M19: Set
A20: 1-5/6-10/11 or more | B20: 10 | C20: Ranking of Catch of fleet in TINC database (use data catalogue) | D20: 1-5 | E20: 1-5 | F20: 1-5 | G20: 1-5 | H20: 6-10 | I20: 1-5 | K20: 1-5 | L20: 1-5 | M20: 1-5
A21: 0-5 year/6-10 years/11-20 years/Longer than 20 years | B21: 11 | C21: Length of Time Series | D21: longer than 20 years | E21: longer than 20 years | F21: longer than 20 years | G21: longer than 20 years | H21: 11-20 years | I21: longer than 20 years | K21: 11-20 years | L21: longer than 20 years | M21: longer than 20 years
A22: None/Few/Many | B22: 12 | C22: Are other indices available for the same time period? | D22: Many | E22: Many | F22: Many | G22: Few | H22: Many | I22: Many | K22: Many | L22: Many | M22: Many
A23: None/Few/Many | B23: 13 | C23: Are other indices available for the same geographic range? | D23: Few | E23: Few | F23: Few | G23: Few | H23: None | I23: Few | K23: Few | L23: Few | M23: Few
A24: Yes/No | B24: 14 | C24: Does the index standardization account for Known factors that influence catchability/selectivity? (e.g. Type of hook, bait type, depth etc.) | D24: Yes | E24: Yes | F24: Yes | G24: Yes | H24: Yes | I24: Yes | K24: Yes | L24: Yes | M24: Yes
... A28: Yes/No | B28: 18 | C28: Is this standardised CPUE time series continuous? | D28: No | E28: Yes | F28: Yes | G28: No | H28: Yes | I28: No | K28: Yes | L28: Yes | M28: Yes
A29: Acoustic/Aerial/Larval/Other (explain below) | B29: 19 | C29: For fisheries independent surveys: what is the survey type?
A30: Yes/No | B30: 20 | C30: For 19: Is the survey design clearly described?
B31: 21 | C31: Other comments | E31: The authors recomend the use of the index that considers vessel as covariate in the model | G31: CV: Moderately low and relatively stable, with only a few years showing notably high values | I31: (2) for recent years, (5-7) use all available data; only late period was used previously (1998-2020) | K31: Gear configuration and environmental factors were used. | L31: Gear configuration and environmental factors were used. | M31: Not to split the time series (1994-2020)

Sheet MED_CPUE_2026
A1: Table X. Available abundance indices for the Mediterranean in 2026.
A2: updated | R2: https://iccat.int/Documents/CVSP/CV066_2011/n_4/CV066041495.pdf
B3: =+COUNT(B14:B51) -> 38 | D3: =+COUNT(D14:D51) -> 19 | F3: =+COUNT(F14:F51) -> 14 | H3: =+COUNT(H14:H51) -> 14 | J3: =+COUNT(J14:J51) -> 13 | L3: =+COUNT(L14:L51) -> 37 | N3: =+COUNT(N14:N51) -> 37 | P3: =+COUNT(P14:P51) -> 13 | R3: =+COUNT(R14:R51) -> 17
A4: series | B4: GRC_LL | D4: w_LIG_LL_early | F4: w_LIG_LL* | H4: n_LIG_LL* | J4: LIG_LLAM_Nominal | L4: n_SPN LL | N4: w_SPN LL | P4: MOR_LL | R4: SIC_GN
A5: Use in 2026 SA | B5: Yes | D5: Sensitivity only | F5: Yes (the author suggested the index in weight that has better model diagnostics) | J5: No | L5: Yes (the authors suggest the index in weight) | P5: Yes | R5: Sensitivity only
A6: Use in 2020 SA | B6: Yes | D6: Sensitivity only | F6: Yes | H6: No | J6: No | L6: Yes | N6: No | P6: Yes | R6: No
A7: age range
A8: units of index | B8: Weight (kg) | D8: Weight (kg) | F8: Weight (kg) | H8: Number | J8: Weight (kg) | L8: Number | N8: Weight (kg) | P8: Weight (kg) | R8: Weight (kg)
A9: area | B9: Eastern Med | D9: Western Med | F9: Western Med | H9: Western Med | J9: Western Med | L9: Western Med | N9: Western Med | P9: Western Med | R9: Western Med
A10: method | B10: GAMM | D10: GLM | F10: GLM | H10: GLM | J10: Nominal CPUE | L10: GLMM | N10: GLMM | P10: GLMM | R10: GLM
A11: time of the year | B11: all months | F11: April–December | H11: April–December | J11: April–May and October–December
A12: source | B12: SCRS/2026/039 | D12: SCRS/2014/112 | F12: SCRS/2026/042 | H12: SCRS/2026/042 | J12: SCRS/2026/042 | L12: SCRS/2026/029 | N12: SCRS/2026/029 | P12: SCRS/2026/048 | R12: SCRS/2010/085
A13: Year | B13: Std. | C13: CV | D13: Std. | E13: CV | F13: Std. | G13: CV | H13: Std. | I13: CV | J13: value | K13: CV | L13: Std. | M13: CV** | N13: Std. | O13: CV** | P13: Std. | Q13: CV | R13: Std. | S13: CV
A14: 1987 | B14: 181.7 | C14: 0.092845349
A15: 1988 | B15: 213.31 | C15: 0.097838826 | L15: 11.7582 | M15: 0.13222262 | N15: 128.575 | O15: 0.18425822
A16: 1989 | B16: 247.25 | C16: 0.13435794 | L16: 4.1086 | M16: 0.23314511 | N16: 115.4062 | O16: 0.29314716
A17: 1990 | B17: 186.44 | C17: 0.077236644 | L17: 4.6593 | M17: 0.209774 | N17: 122.1755 | O17: 0.26478222 | R17: 8.31
A18: 1991 | B18: 228.97 | C18: 0.063545443 | D18: 88.467336 | L18: 7.3097 | M18: 0.13271406 | N18: 86.7179 | O18: 0.18281808 | R18: 9.8
A19: 1992 | B19: 100.21 | C19: 0.061470911 | D19: 66.100051 | L19: 8.2662 | M19: 0.1322494 | N19: 74.2483 | O19: 0.18282978 | R19: 16.87
A20: 1993 | B20: 151.64 | C20: 0.064099182 | D20: 68.763321 | L20: 8.2301 | M20: 0.13149293 | N20: 98.0339 | O20: 0.1817708 | R20: 13.04
A21: 1994 | B21: 175.7 | C21: 0.061752988 | D21: 90.595943 | L21: 10.362 | M21: 0.13071801 | N21: 119.9387 | O21: 0.18113336 | R21: 9.49
A22: 1995 | B22: 119.98 | C22: 0.074095683 | D22: 94.617415 | L22: 8.754 | M22: 0.13014622 | N22: 94.2404 | O22: 0.18057754 | R22: 14.65
A23: 1996 | B23: 181.7 | C23: 0.092845349 | D23: 94.344342 | L23: 5.9796 | M23: 0.13099538 | N23: 80.784 | O23: 0.18135274 | R23: 9.33
A24: 1997 | B24: 256.78 | C24: 0.096424955 | D24: 101.06904 | L24: 5.742 | M24: 0.13279345 | N24: 82.5939 | O24: 0.18290213 | R24: 14.04
A25: 1998 | B25: 239.03 | C25: 0.06639334 | D25: 144.93701 | L25: 7.0884 | M25: 0.13184922 | N25: 92.9999 | O25: 0.18231955 | R25: 10.12
A26: 1999 | B26: 208.38 | C26: 0.053412036 | D26: 101.89597 | L26: 5.6138 | M26: 0.13256618 | N26: 85.8754 | O26: 0.1829057 | R26: 12.71
A27: 2000 | B27: 171.51 | C27: 0.049268264 | D27: 134.68065 | L27: 4.6591 | M27: 0.23180443 | N27: 121.4987 | O27: 0.29951596 | R27: 14.92
A28: 2001 | B28: 174.74 | C28: 0.057571249 | D28: 181.62454 | L28: 6.0998 | M28: 0.14033247 | N28: 83.6254 | O28: 0.19159849 | R28: 13.06
A29: 2002 | B29: 143.12 | C29: 0.069661822 | D29: 140.32481 | L29: 11.2956 | M29: 0.13580509 | N29: 125.3074 | O29: 0.18656919
A30: 2003 | B30: 170.91 | C30: 0.056989059 | D30: 152.27809 | L30: 7.076 | M30: 0.13849633 | N30: 80.7836 | O30: 0.19033938
A31: 2004 | B31: 172.18 | C31: 0.051399698 | D31: 98.857786 | L31: 5.0777 | M31: 0.13840912 | N31: 60.1142 | O31: 0.1890352 | R31: 15.15
A32: 2005 | B32: 170.75 | C32: 0.048023426 | D32: 80.801294 | L32: 6.2752 | M32: 0.14315082 | N32: 81.7071 | O32: 0.19505037 | R32: 12.07
A33: 2006 | B33: 180.52 | C33: 0.052459561 | D33: 125.04794 | L33: 7.0103 | M33: 0.15086373 | N33: 108.5994 | O33: 0.20428105 | R33: 30.74
A34: 2007 | B34: 183.8 | C34: 0.052067465 | D34: 239.99924 | L34: 9.3298 | M34: 0.13992797 | N34: 118.5871 | O34: 0.19177212
A35: 2008 | B35: 171.93 | C35: 0.067643809 | D35: 208.17563 | L35: 8.6974 | M35: 0.13690298 | N35: 153.3728 | O35: 0.18763823 | R35: 3.29
A36: 2009 | B36: 159.22 | C36: 0.061047607 | D36: 123.38733 | L36: 4.9981 | M36: 0.1339509 | N36: 99.0274 | O36: 0.18438937 | R36: 1.97
A37: 2010 | B37: 178.51 | C37: 0.061789256 | F37: 336.73 | G37: 0.06 | H37: 8.95 | I37: 0.06 | L37: 5.5176 | M37: 0.13379005 | N37: 106.1998 | O37: 0.18374705
A38: 2011 | B38: 149.11 | C38: 0.071088458 | F38: 246.91 | G38: 0.05 | H38: 7.69 | I38: 0.04 | L38: 6.2457 | M38: 0.13295547 | N38: 101.9984 | O38: 0.18334601
A39: 2012 | B39: 137.98 | C39: 0.079794173 | F39: 156.27 | G39: 0.05 | H39: 6.08 | I39: 0.04 | J39: 72.1 | L39: 8.5124 | M39: 0.13398102 | N39: 135.0474 | O39: 0.1847655 | P39: 111.1996 | Q39: 0.0375
A40: 2013 | B40: 217.8 | C40: 0.073875115 | F40: 171.67 | G40: 0.05 | H40: 5.9 | I40: 0.05 | J40: 140.2 | L40: 6.6513 | M40: 0.13000466 | N40: 89.2538 | O40: 0.18037887 | P40: 155.757 | Q40: 0.0298
...

Sheet Med_Figure
O1: East/W | P1: West/W | Q1: West/W | R1: West/n | T1: West/n | U1: West/W | V1: West/W | W1: West/W
A2: mean_per | B2: =+AVERAGE(B6:B43) -> 166.34868 | C2: =+AVERAGE(C6:C43) -> 122.94567 | D2: =+AVERAGE(D6:D43) -> 191.13571 | E2: =+AVERAGE(E6:E43) -> 6.4192857 | F2: =+AVERAGE(F6:F43) -> 110.19231 | G2: =+AVERAGE(G6:G43) -> 6.837727 | H2: =+AVERAGE(H6:H43) -> 98.546668 | I2: =+AVERAGE(I6:I43) -> 74.323131 | J2: =+AVERAGE(J6:J43) -> 12.327059 | O2: scaled to mean | S2: Nominal
B3: =+COUNT(B6:B68) -> 38 | C3: =+COUNT(C6:C68) -> 19 | D3: =+COUNT(D6:D68) -> 14 | E3: =+COUNT(E6:E68) -> 14 | F3: =+COUNT(F6:F68) -> 13 | G3: =+COUNT(G6:G68) -> 37 | H3: =+COUNT(H6:H68) -> 37 | I3: =+COUNT(I6:I68) -> 13 | J3: =+COUNT(J6:J68) -> 17 | P3: =+COUNT(P6:P43)-C3 -> 0 | Q3: =+COUNT(Q6:Q43)-D3 -> 0 | R3: =+COUNT(R6:R43)-E3 -> 0 | S3: =+COUNT(S6:S43)-F3 -> 0 | T3: =+COUNT(T6:T43)-G3 -> 0 | U3: =+COUNT(U6:U43)-H3 -> 0 | V3: =+COUNT(V6:V43)-I3 -> 0 | W3: =+COUNT(W6:W43)-J3 -> 0
B4: =+MED_CPUE_2026!B3 -> 38 | C4: =+MED_CPUE_2026!D3 -> 19 | D4: =+MED_CPUE_2026!F3 -> 14 | E4: =+MED_CPUE_2026!H3 -> 14 | F4: =+MED_CPUE_2026!J3 -> 13 | G4: =+MED_CPUE_2026!L3 -> 37 | H4: =+MED_CPUE_2026!N3 -> 37 | I4: =+MED_CPUE_2026!P3 -> 13 | J4: =+MED_CPUE_2026!R3 -> 17
A5: Year | B5: =+MED_CPUE_2026!B4 -> GRC_LL | C5: =+MED_CPUE_2026!D4 -> w_LIG_LL_early | D5: =+MED_CPUE_2026!F4 -> w_LIG_LL* | E5: =+MED_CPUE_2026!H4 -> n_LIG_LL* | F5: =+MED_CPUE_2026!J4 -> LIG_LLAM_Nominal | G5: =+MED_CPUE_2026!L4 -> n_SPN LL | H5: =+MED_CPUE_2026!N4 -> w_SPN LL | I5: =+MED_CPUE_2026!P4 -> MOR_LL | J5: =+MED_CPUE_2026!R4 -> SIC_GN | O5: =+B5 -> GRC_LL | P5: =+C5 -> w_LIG_LL_early | Q5: =+D5 -> w_LIG_LL* | R5: =+E5 -> n_LIG_LL* | S5: =+F5 -> LIG_LLAM_Nominal | T5: =+G5 -> n_SPN LL | U5: =+H5 -> w_SPN LL | V5: =+I5 -> MOR_LL | W5: =+J5 -> SIC_GN
A6: =+MED_CPUE_2026!A14 -> 1987 | B6: =+MED_CPUE_2026!B14 -> 181.7 | N6: =+A6 -> 1987 | O6: =+B6/B$2 -> 1.092284
A7: =+MED_CPUE_2026!A15 -> 1988 | B7: =+MED_CPUE_2026!B15 -> 213.31 | G7: =+MED_CPUE_2026!L15 -> 11.7582 | H7: =+MED_CPUE_2026!N15 -> 128.575 | N7: =+A7 -> 1988 | O7: =+B7/B$2 -> 1.2823065 | T7: =+G7/G$2 -> 1.7196065 | U7: =+H7/H$2 -> 1.3047118
A8: =+MED_CPUE_2026!A16 -> 1989 | B8: =+MED_CPUE_2026!B16 -> 247.25 | G8: =+MED_CPUE_2026!L16 -> 4.1086 | H8: =+MED_CPUE_2026!N16 -> 115.4062 | N8: =+A8 -> 1989 | O8: =+B8/B$2 -> 1.4863358 | T8: =+G8/G$2 -> 0.60087219 | U8: =+H8/H$2 -> 1.1710817
A9: =+MED_CPUE_2026!A17 -> 1990 | B9: =+MED_CPUE_2026!B17 -> 186.44 | G9: =+MED_CPUE_2026!L17 -> 4.6593 | H9: =+MED_CPUE_2026!N17 -> 122.1755 | J9: =+MED_CPUE_2026!R17 -> 8.31 | N9: =+A9 -> 1990 | O9: =+B9/B$2 -> 1.1207783 | T9: =+G9/G$2 -> 0.68141065 | U9: =+H9/H$2 -> 1.239773 | W9: =+J9/J$2 -> 0.67412674
A10: =+MED_CPUE_2026!A18 -> 1991 | B10: =+MED_CPUE_2026!B18 -> 228.97 | C10: =+MED_CPUE_2026!D18 -> 88.467336 | G10: =+MED_CPUE_2026!L18 -> 7.3097 | H10: =+MED_CPUE_2026!N18 -> 86.7179 | J10: =+MED_CPUE_2026!R18 -> 9.8 | N10: =+A10 -> 1991 | O10: =+B10/B$2 -> 1.3764461 | P10: =+C10/C$2 -> 0.71956447 | T10: =+G10/G$2 -> 1.0690248 | U10: =+H10/H$2 -> 0.87996786 | W10: =+J10/J$2 -> 0.79499905
A11: =+MED_CPUE_2026!A19 -> 1992 | B11: =+MED_CPUE_2026!B19 -> 100.21 | C11: =+MED_CPUE_2026!D19 -> 66.100051 | G11: =+MED_CPUE_2026!L19 -> 8.2662 | H11: =+MED_CPUE_2026!N19 -> 74.2483 | J11: =+MED_CPUE_2026!R19 -> 16.87 | N11: =+A11 -> 1992 | O11: =+B11/B$2 -> 0.60240933 | P11: =+C11/C$2 -> 0.53763626 | T11: =+G11/G$2 -> 1.2089105 | U11: =+H11/H$2 -> 0.75343288 | W11: =+J11/J$2 -> 1.3685341
A12: =+MED_CPUE_2026!A20 -> 1993 | B12: =+MED_CPUE_2026!B20 -> 151.64 | C12: =+MED_CPUE_2026!D20 -> 68.763321 | G12: =+MED_CPUE_2026!L20 -> 8.2301 | H12: =+MED_CPUE_2026!N20 -> 98.0339 | J12: =+MED_CPUE_2026!R20 -> 13.04 | N12: =+A12 -> 1993 | O12: =+B12/B$2 -> 0.9115792 | P12: =+C12/C$2 -> 0.55929843 | T12: =+G12/G$2 -> 1.203631 | U12: =+H12/H$2 -> 0.9947967 | W12: =+J12/J$2 -> 1.0578355
A13: =+MED_CPUE_2026!A21 -> 1994 | B13: =+MED_CPUE_2026!B21 -> 175.7 | C13: =+MED_CPUE_2026!D21 -> 90.595943 | G13: =+MED_CPUE_2026!L21 -> 10.362 | H13: =+MED_CPUE_2026!N21 -> 119.9387 | J13: =+MED_CPUE_2026!R21 -> 9.49 | N13: =+A13 -> 1994 | O13: =+B13/B$2 -> 1.0562151 | P13: =+C13/C$2 -> 0.73687787 | T13: =+G13/G$2 -> 1.5154159 | U13: =+H13/H$2 -> 1.2170751 | W13: =+J13/J$2 -> 0.76985112
A14: =+MED_CPUE_2026!A22 -> 1995 | B14: =+MED_CPUE_2026!B22 -> 119.98 | C14: =+MED_CPUE_2026!D22 -> 94.617415 | G14: =+MED_CPUE_2026!L22 -> 8.754 | H14: =+MED_CPUE_2026!N22 -> 94.2404 | J14: =+MED_CPUE_2026!R22 -> 14.65 | N14: =+A14 -> 1995 | O14: =+B14/B$2 -> 0.72125608 | P14: =+C14/C$2 -> 0.7695872 | T14: =+G14/G$2 -> 1.28025 | U14: =+H14/H$2 -> 0.95630225 | W14: =+J14/J$2 -> 1.1884425
A15: =+MED_CPUE_2026!A23 -> 1996 | B15: =+MED_CPUE_2026!B23 -> 181.7 | C15: =+MED_CPUE_2026!D23 -> 94.344342 | G15: =+MED_CPUE_2026!L23 -> 5.9796 | H15: =+MED_CPUE_2026!N23 -> 80.784 | J15: =+MED_CPUE_2026!R23 -> 9.33 | N15: =+A15 -> 1996 | O15: =+B15/B$2 -> 1.092284 | P15: =+C15/C$2 -> 0.76736611 | T15: =+G15/G$2 -> 0.87450113 | U15: =+H15/H$2 -> 0.81975375 | W15: =+J15/J$2 -> 0.75687154
A16: =+MED_CPUE_2026!A24 -> 1997 | B16: =+MED_CPUE_2026!B24 -> 256.78 | C16: =+MED_CPUE_2026!D24 -> 101.06904 | G16: =+MED_CPUE_2026!L24 -> 5.742 | H16: =+MED_CPUE_2026!N24 -> 82.5939 | J16: =+MED_CPUE_2026!R24 -> 14.04 | N16: =+A16 -> 1997 | O16: =+B16/B$2 -> 1.5436251 | P16: =+C16/C$2 -> 0.82206263 | T16: =+G16/G$2 -> 0.83975274 | U16: =+H16/H$2 -> 0.83811966 | W16: =+J16/J$2 -> 1.1389578
A17: =+MED_CPUE_2026!A25 -> 1998 | B17: =+MED_CPUE_2026!B25 -> 239.03 | C17: =+MED_CPUE_2026!D25 -> 144.93701 | G17: =+MED_CPUE_2026!L25 -> 7.0884 | H17: =+MED_CPUE_2026!N25 -> 92.9999 | J17: =+MED_CPUE_2026!R25 -> 10.12 | N17: =+A17 -> 1998 | O17: =+B17/B$2 -> 1.4369215 | P17: =+C17/C$2 -> 1.1788704 | T17: =+G17/G$2 -> 1.0366603 | U17: =+H17/H$2 -> 0.94371431 | W17: =+J17/J$2 -> 0.8209582
A18: =+MED_CPUE_2026!A26 -> 1999 | B18: =+MED_CPUE_2026!B26 -> 208.38 | C18: =+MED_CPUE_2026!D26 -> 101.89597 | G18: =+MED_CPUE_2026!L26 -> 5.6138 | H18: =+MED_CPUE_2026!N26 -> 85.8754 | J18: =+MED_CPUE_2026!R26 -> 12.71 | N18: =+A18 -> 1999 | O18: =+B18/B$2 -> 1.25267 | P18: =+C18/C$2 -> 0.82878861 | T18: =+G18/G$2 -> 0.82100382 | U18: =+H18/H$2 -> 0.87141861 | W18: =+J18/J$2 -> 1.0310651
A19: =+MED_CPUE_2026!A27 -> 2000 | B19: =+MED_CPUE_2026!B27 -> 171.51 | C19: =+MED_CPUE_2026!D27 -> 134.68065 | G19: =+MED_CPUE_2026!L27 -> 4.6591 | H19: =+MED_CPUE_2026!N27 -> 121.4987 | J19: =+MED_CPUE_2026!R27 -> 14.92 | N19: =+A19 -> 2000 | O19: =+B19/B$2 -> 1.0310271 | P19: =+C19/C$2 -> 1.0954485 | T19: =+G19/G$2 -> 0.6813814 | U19: =+H19/H$2 -> 1.2329052 | W19: =+J19/J$2 -> 1.2103455
A20: =+MED_CPUE_2026!A28 -> 2001 | B20: =+MED_CPUE_2026!B28 -> 174.74 | C20: =+MED_CPUE_2026!D28 -> 181.62454 | G20: =+MED_CPUE_2026!L28 -> 6.0998 | H20: =+MED_CPUE_2026!N28 -> 83.6254 | J20: =+MED_CPUE_2026!R28 -> 13.06 | N20: =+A20 -> 2001 | O20: =+B20/B$2 -> 1.0504441 | P20: =+C20/C$2 -> 1.4772748 | T20: =+G20/G$2 -> 0.89208007 | U20: =+H20/H$2 -> 0.84858679 | W20: =+J20/J$2 -> 1.0594579
A21: =+MED_CPUE_2026!A29 -> 2002 | B21: =+MED_CPUE_2026!B29 -> 143.12 | C21: =+MED_CPUE_2026!D29 -> 140.32481 | G21: =+MED_CPUE_2026!L29 -> 11.2956 | H21: =+MED_CPUE_2026!N29 -> 125.3074 | N21: =+A21 -> 2002 | O21: =+B21/B$2 -> 0.86036148 | P21: =+C21/C$2 -> 1.1413563 | T21: =+G21/G$2 -> 1.6519525 | U21: =+H21/H$2 -> 1.2715539
A22: =+MED_CPUE_2026!A30 -> 2003 | B22: =+MED_CPUE_2026!B30 -> 170.91 | C22: =+MED_CPUE_2026!D30 -> 152.27809 | G22: =+MED_CPUE_2026!L30 -> 7.076 | H22: =+MED_CPUE_2026!N30 -> 80.7836 | N22: =+A22 -> 2003 | O22: =+B22/B$2 -> 1.0274202 | P22: =+C22/C$2 -> 1.2385803 | T22: =+G22/G$2 -> 1.0348468 | U22: =+H22/H$2 -> 0.81974969
A23: =+MED_CPUE_2026!A31 -> 2004 | B23: =+MED_CPUE_2026!B31 -> 172.18 | C23: =+MED_CPUE_2026!D31 -> 98.857786 | G23: =+MED_CPUE_2026!L31 -> 5.0777 | H23: =+MED_CPUE_2026!N31 -> 60.1142 | J23: =+MED_CPUE_2026!R31 -> 15.15 | N23: =+A23 -> 2004 | O23: =+B23/B$2 -> 1.0350548 | P23: =+C23/C$2 -> 0.804077 | T23: =+G23/G$2 -> 0.74260057 | U23: =+H23/H$2 -> 0.61000744 | W23: =+J23/J$2 -> 1.2290036
A24: =+MED_CPUE_2026!A32 -> 2005 | B24: =+MED_CPUE_2026!B32 -> 170.75 | C24: =+MED_CPUE_2026!D32 -> 80.801294 | G24: =+MED_CPUE_2026!L32 -> 6.2752 | H24: =+MED_CPUE_2026!N32 -> 81.7071 | J24: =+MED_CPUE_2026!R32 -> 12.07 | N24: =+A24 -> 2005 | O24: =+B24/B$2 -> 1.0264584 | P24: =+C24/C$2 -> 0.65721138 | T24: =+G24/G$2 -> 0.91773187 | U24: =+H24/H$2 -> 0.82912088 | W24: =+J24/J$2 -> 0.97914678
A25: =+MED_CPUE_2026!A33 -> 2006 | B25: =+MED_CPUE_2026!B33 -> 180.52 | C25: =+MED_CPUE_2026!D33 -> 125.04794 | G25: =+MED_CPUE_2026!L33 -> 7.0103 | H25: =+MED_CPUE_2026!N33 -> 108.5994 | J25: =+MED_CPUE_2026!R33 -> 30.74 | N25: =+A25 -> 2006 | O25: =+B25/B$2 -> 1.0851904 | P25: =+C25/C$2 -> 1.0170992 | T25: =+G25/G$2 -> 1.0252384 | U25: =+H25/H$2 -> 1.1020099 | W25: =+J25/J$2 -> 2.4937011
A26: =+MED_CPUE_2026!A34 -> 2007 | B26: =+MED_CPUE_2026!B34 -> 183.8 | C26: =+MED_CPUE_2026!D34 -> 239.99924 | G26: =+MED_CPUE_2026!L34 -> 9.3298 | H26: =+MED_CPUE_2026!N34 -> 118.5871 | N26: =+A26 -> 2007 | O26: =+B26/B$2 -> 1.104908 | P26: =+C26/C$2 -> 1.9520756 | T26: =+G26/G$2 -> 1.3644593 | U26: =+H26/H$2 -> 1.2033598
A27: =+MED_CPUE_2026!A35 -> 2008 | B27: =+MED_CPUE_2026!B35 -> 171.93 | C27: =+MED_CPUE_2026!D35 -> 208.17563 | G27: =+MED_CPUE_2026!L35 -> 8.6974 | H27: =+MED_CPUE_2026!N35 -> 153.3728 | J27: =+MED_CPUE_2026!R35 -> 3.29 | N27: =+A27 -> 2008 | O27: =+B27/B$2 -> 1.0335519 | P27: =+C27/C$2 -> 1.6932327 | T27: =+G27/G$2 -> 1.2719724 | U27: =+H27/H$2 -> 1.5563469 | W27: =+J27/J$2 -> 0.26689254
A28: =+MED_CPUE_2026!A36 -> 2009 | B28: =+MED_CPUE_2026!B36 -> 159.22 | C28: =+MED_CPUE_2026!D36 -> 123.38733 | G28: =+MED_CPUE_2026!L36 -> 4.9981 | H28: =+MED_CPUE_2026!N36 -> 99.0274 | J28: =+MED_CPUE_2026!R36 -> 1.97 | N28: =+A28 -> 2009 | O28: =+B28/B$2 -> 0.95714613 | P28: =+C28/C$2 -> 1.0035923 | T28: =+G28/G$2 -> 0.73095928 | U28: =+H28/H$2 -> 1.0048782 | W28: =+J28/J$2 -> 0.15981103
A29: =+MED_CPUE_2026!A37 -> 2010 | B29: =+MED_CPUE_2026!B37 -> 178.51 | D29: =+MED_CPUE_2026!F37 -> 336.73 | E29: =+MED_CPUE_2026!H37 -> 8.95 | G29: =+MED_CPUE_2026!L37 -> 5.5176 | H29: =+MED_CPUE_2026!N37 -> 106.1998 | N29: =+A29 -> 2010 | O29: =+B29/B$2 -> 1.0731074 | Q29: =+D29/D$2 -> 1.7617325 | R29: =+E29/E$2 -> 1.3942361 | T29: =+G29/G$2 -> 0.80693482 | U29: =+H29/H$2 -> 1.07766
A30: =+MED_CPUE_2026!A38 -> 2011 | B30: =+MED_CPUE_2026!B38 -> 149.11 | D30: =+MED_CPUE_2026!F38 -> 246.91 | E30: =+MED_CPUE_2026!H38 -> 7.69 | G30: =+MED_CPUE_2026!L38 -> 6.2457 | H30: =+MED_CPUE_2026!N38 -> 101.9984 | N30: =+A30 -> 2011 | O30: =+B30/B$2 -> 0.89637018 | Q30: =+D30/D$2 -> 1.2918046 | R30: =+E30/E$2 -> 1.1979526 | T30: =+G30/G$2 -> 0.91341757 | U30: =+H30/H$2 -> 1.0350264
A31: =+MED_CPUE_2026!A39 -> 2012 | B31: =+MED_CPUE_2026!B39 -> 137.98 | D31: =+MED_CPUE_2026!F39 -> 156.27 | E31: =+MED_CPUE_2026!H39 -> 6.08 | F31: =+MED_CPUE_2026!J39 -> 72.1 | G31: =+MED_CPUE_2026!L39 -> 8.5124 | H31: =+MED_CPUE_2026!N39 -> 135.0474 | I31: =+MED_CPUE_2026!P39 -> 111.1996 | N31: =+A31 -> 2012 | O31: =+B31/B$2 -> 0.82946253 | Q31: =+D31/D$2 -> 0.81758661 | R31: =+E31/E$2 -> 0.94714588 | S31: =+F31/F$2 -> 0.65431065 | T31: =+G31/G$2 -> 1.2449166 | U31: =+H31/H$2 -> 1.3703903 | V31: =+I31/I$2 -> 1.4961641
A32: =+MED_CPUE_2026!A40 -> 2013 | B32: =+MED_CPUE_2026!B40 -> 217.8 | D32: =+MED_CPUE_2026!F40 -> 171.67 | E32: =+MED_CPUE_2026!H40 -> 5.9 | F32: =+MED_CPUE_2026!J40 -> 140.2 | G32: =+MED_CPUE_2026!L40 -> 6.6513 | H32: =+MED_CPUE_2026!N40 -> 89.2538 | I32: =+MED_CPUE_2026!P40 -> 155.757 | N32: =+A32 -> 2013 | O32: =+B32/B$2 -> 1.309298 | Q32: =+D32/D$2 -> 0.89815763 | R32: =+E32/E$2 -> 0.91910537 | S32: =+F32/F$2 -> 1.2723211 | T32: =+G32/G$2 -> 0.97273553 | U32: =+H32/H$2 -> 0.90570084 | V32: =+I32/I$2 -> 2.0956733
A33: =+MED_CPUE_2026!A41 -> 2014 | B33: =+MED_CPUE_2026!B41 -> 171.6 | D33: =+MED_CPUE_2026!F41 -> 245.33 | E33: =+MED_CPUE_2026!H41 -> 9.6 | F33: =+MED_CPUE_2026!J41 -> 140.9 | G33: =+MED_CPUE_2026!L41 -> 6.8519 | H33: =+MED_CPUE_2026!N41 -> 96.4352 | I33: =+MED_CPUE_2026!P41 -> 77.2664 | N33: =+A33 -> 2014 | O33: =+B33/B$2 -> 1.0315681 | Q33: =+D33/D$2 -> 1.2835382 | R33: =+E33/E$2 -> 1.4954935 | S33: =+F33/F$2 -> 1.2786736 | T33: =+G33/G$2 -> 1.0020728 | U33: =+H33/H$2 -> 0.97857393 | V33: =+I33/I$2 -> 1.039601
A34: =+MED_CPUE_2026!A42 -> 2015 | B34: =+MED_CPUE_2026!B42 -> 148.27 | D34: =+MED_CPUE_2026!F42 -> 158.99 | E34: =+MED_CPUE_2026!H42 -> 5.36 | F34: =+MED_CPUE_2026!J42 -> 180.3 | G34: =+MED_CPUE_2026!L42 -> 6.8243 | H34: =+MED_CPUE_2026!N42 -> 86.1278 | I34: =+MED_CPUE_2026!P42 -> 88.1798 | N34: =+A34 -> 2015 | O34: =+B34/B$2 -> 0.89132055 | Q34: =+D34/D$2 -> 0.83181733 | R34: =+E34/E$2 -> 0.83498387 | S34: =+F34/F$2 -> 1.6362304 | T34: =+G34/G$2 -> 0.99803633 | U34: =+H34/H$2 -> 0.87397983 | V34: =+I34/I$2 -> 1.1864382
A35: =+MED_CPUE_2026!A43 -> 2016 | B35: =+MED_CPUE_2026!B43 -> 165.22 | D35: =+MED_CPUE_2026!F43 -> 197.82 | E35: =+MED_CPUE_2026!H43 -> 7.7 | F35: =+MED_CPUE_2026!J43 -> 132.6 | G35: =+MED_CPUE_2026!L43 -> 6.8735 | H35: =+MED_CPUE_2026!N43 -> 70.5992 | I35: =+MED_CPUE_2026!P43 -> 87.3184 | N35: =+A35 -> 2016 | O35: =+B35/B$2 -> 0.99321495 | Q35: =+D35/D$2 -> 1.0349714 | R35: =+E35/E$2 -> 1.1995104 | S35: =+F35/F$2 -> 1.2033508 | T35: =+G35/G$2 -> 1.0052317 | U35: =+H35/H$2 -> 0.71640373 | V35: =+I35/I$2 -> 1.1748482
A36: =+MED_CPUE_2026!A44 -> 2017 | B36: =+MED_CPUE_2026!B44 -> 108.6 | D36: =+MED_CPUE_2026!F44 -> 179.97 | E36: =+MED_CPUE_2026!H44 -> 6.46 | F36: =+MED_CPUE_2026!J44 -> 117.7 | G36: =+MED_CPUE_2026!L44 -> 6.4326 | H36: =+MED_CPUE_2026!N44 -> 124.6284 | I36: =+MED_CPUE_2026!P44 -> 57.4235 | N36: =+A36 -> 2017 | O36: =+B36/B$2 -> 0.65284556 | Q36: =+D36/D$2 -> 0.94158227 | R36: =+E36/E$2 -> 1.0063425 | S36: =+F36/F$2 -> 1.0681326 | T36: =+G36/G$2 -> 0.94075121 | U36: =+H36/H$2 -> 1.2646638 | V36: =+I36/I$2 -> 0.7726195
A37: =+MED_CPUE_2026!A45 -> 2018 | B37: =+MED_CPUE_2026!B45 -> 123.62 | D37: =+MED_CPUE_2026!F45 -> 121.06 | E37: =+MED_CPUE_2026!H45 -> 4.12 | F37: =+MED_CPUE_2026!J45 -> 74.2 | G37: =+MED_CPUE_2026!L45 -> 5.1405 | H37: =+MED_CPUE_2026!N45 -> 106.9404 | I37: =+MED_CPUE_2026!P45 -> 63.6291 | N37: =+A37 -> 2018 | O37: =+B37/B$2 -> 0.74313783 | Q37: =+D37/D$2 -> 0.63337195 | R37: =+E37/E$2 -> 0.64181596 | S37: =+F37/F$2 -> 0.67336824 | T37: =+G37/G$2 -> 0.75178491 | U37: =+H37/H$2 -> 1.0851752 | V37: =+I37/I$2 -> 0.85611437
A38: =+MED_CPUE_2026!A46 -> 2019 | B38: =+MED_CPUE_2026!B46 -> 128.25 | D38: =+MED_CPUE_2026!F46 -> 176.47 | E38: =+MED_CPUE_2026!H46 -> 5.74 | F38: =+MED_CPUE_2026!J46 -> 117.3 | G38: =+MED_CPUE_2026!L46 -> 4.7872 | H38: =+MED_CPUE_2026!N46 -> 79.2055 | I38: =+MED_CPUE_2026!P46 -> 47.1454 | N38: =+A38 -> 2019 | O38: =+B38/B$2 -> 0.77097093 | Q38: =+D38/D$2 -> 0.92327068 | R38: =+E38/E$2 -> 0.89418048 | S38: =+F38/F$2 -> 1.0645026 | T38: =+G38/G$2 -> 0.70011569 | U38: =+H38/H$2 -> 0.80373596 | V38: =+I38/I$2 -> 0.63433011
A39: =+MED_CPUE_2026!A47 -> 2020 | B39: =+MED_CPUE_2026!B47 -> 138.79 | D39: =+MED_CPUE_2026!F47 -> 209.34 | E39: =+MED_CPUE_2026!H47 -> 7.13 | F39: =+MED_CPUE_2026!J47 -> 76.9 | G39: =+MED_CPUE_2026!L47 -> 5.1363 | H39: =+MED_CPUE_2026!N47 -> 77.893 | I39: =+MED_CPUE_2026!P47 -> 53.6624 | N39: =+A39 -> 2020 | O39: =+B39/B$2 -> 0.83433182 | Q39: =+D39/D$2 -> 1.0952427 | R39: =+E39/E$2 -> 1.1107155 | S39: =+F39/F$2 -> 0.69787086 | T39: =+G39/G$2 -> 0.75117067 | U39: =+H39/H$2 -> 0.79041739 | V39: =+I39/I$2 -> 0.72201479
A40: =+MED_CPUE_2026!A48 -> 2021 | B40: =+MED_CPUE_2026!B48 -> 143.04 | D40: =+MED_CPUE_2026!F48 -> 125.77 | E40: =+MED_CPUE_2026!H48 -> 4.19 | F40: =+MED_CPUE_2026!J48 -> 67.6 | G40: =+MED_CPUE_2026!L48 -> 6.6537 | H40: =+MED_CPUE_2026!N48 -> 93.605 | I40: =+MED_CPUE_2026!P48 -> 55.357 | N40: =+A40 -> 2021 | O40: =+B40/B$2 -> 0.85988056 | Q40: =+D40/D$2 -> 0.65801413 | R40: =+E40/E$2 -> 0.6527206 | S40: =+F40/F$2 -> 0.61347295 | T40: =+G40/G$2 -> 0.97308652 | U40: =+H40/H$2 -> 0.94985454 | V40: =+I40/I$2 -> 0.74481523
...

Sheet Med_Eval2026
A1: SWODP 2026
D2: weight | E2: weight/number | F2: weight/number | G2: weight
D3: GRC_LL | E3: LIG_LL | F3: SPN_LL | G3: MOR_LL
C4: Stock | D4: Mediterranean | E4: Mediterranean | F4: Mediterranean | G4: Mediterranean
C5: Will be used in current stock assessment? State model/s. | D5: Yes | E5: Yes | F5: Yes | G5: Yes
C6: SCRS Doc No: | D6: SCRS/2026/039 | E6: SCRS/2026/042 | F6: SCRS/2026/029 | G6: SCRS/2026/048
C7: Index Name: | D7: Greece longline | E7: Liguria longline | F7: Spain longline | G7: Morocco longline
C8: Data Source (state if based on logbooks, observer data etc) | D8: Observations at landings and aboard | E8: Observations at landings and aboard | F8: Logbook and observer data | G8: Fish market statistics
C9: Do the authors indicate the percentage of total effort of the fleet the CPUE data represents? | D9: No | E9: Yes | F9: Yes on catches | G9: No
C10: If the answer to 1 is yes, what is the percentage? | E10: 21-30% | F10: 43% latest years
C11: Are sufficient diagnostics provided to assess model performance?? | D11: Sufficient | E11: Sufficient | F11: Sufficient | G11: Sufficient
C12: How does the model perform relative to the diagnostics ? | D12: Well | E12: Well | F12: Well | G12: Well
C13: Documented data exclusions and classifications? | D13: NA | E13: Yes | F13: Yes | G13: NA
C14: Data exclusions appropriate? | D14: NA | E14: Yes | F14: Yes | G14: NA
C15: Data classifications appropriate? | D15: NA | E15: Yes | F15: Yes | G15: NA
C16: Geographical Area | D16: East Med | E16: Ligurian Sea | F16: Western Med | G16: St. Gibrartar, West Med
C17: Data resolution level | D17: trip | E17: trip | F17: trip | G17: trip
C18: Ranking of Catch of fleet in TINC database (use data catalogue) | D18: 1-5 | E18: 11 or more | F18: 1-5 | G18: 1-5
C19: Length of Time Series | D19: longer than 20 years | E19: 11-20 years | F19: longer than 20 years | G19: 11-20 years
C20: Are other indices available for the same time period? | D20: Few | E20: Few | F20: Few | G20: None
C21: Are other indices available for the same geographic range? | D21: None | E21: Few | F21: Few | G21: None
C22: Does the index standardization account for Known factors that influence catchability/selectivity? (eg. Type of hook, bait type, depth etc.) | D22: Yes | E22: Yes | F22: Yes | G22: No
... C26: Is this standardised CPUE time series continuous? | D26: Yes | E26: Yes | F26: Yes | G26: Yes
C27: For fisheries independent surveys: what is the survey type?
C28: For 19: Is the survey design clearly described?
C29: Other Comments | D29: Biomass index (< 10 x 10 degrees) | E29: Index in Numbers and biomass. Recommend to use Biomass index. The total catch by Ligurian is about 6% of the EU-Italy LL. | F29: Index both Numbers and biomass Recommend use Biomass index | G29: Localised (< 10 x 10 degrees)
A32: Retained only; Both | C32: Does the index include discarded and retained fish? | D32: Retained only | E32: Retained Only | F32: Retained only | G32: Retained Only

Sheet Comp2020vs2026
A1: Stock | B1: Med | C1: Med | D1: Med | E1: Med | F1: Med | G1: Med | H1: Med | I1: Med | J1: Med | K1: Med | L1: Med | M1: Med | N1: Med | O1: Med | P1: Med | Q1: Med | R1: Med | S1: Med | T1: Med | U1: Med | V1: Med | W1: Med | X1: Med | Y1: Med | Z1: Med | AA1: Med | AB1: Med | AC1: Med | AD1: Med | AE1: Med | AF1: Med | AG1: Med | AH1: Med | AI1: Med | AJ1: Med | AK1: Med | AL1: Med | AM1: Med | AN1: Med | AO1: Med | AP1: Med | AQ1: Med | AR1: Med | AS1: Med | AT1: Med | AU1: Med | AV1: Med | AW1: Med | AX1: Med | AY1: Med | AZ1: Med | BA1: Med | BB1: Med | BC1: Med | BF1: Stock | BG1: South | BH1: South | BI1: South | BJ1: South | BK1: South | BL1: South | BM1: South | BN1: South | BO1: South | BP1: South | BQ1: South | BR1: South | BS1: South | BT1: South | BU1: South | BV1: South | BW1: South | BX1: South | BY1: South | BZ1: South | CA1: South | CB1: South | CC1: South | CD1: South | CE1: South | CF1: South | CG1: South | CH1: South | CI1: South | CJ1: South | CK1: South | CL1: South | CM1: South | CN1: South | CO1: South | CP1: South | CQ1: South | CR1: South | CS1: South | CT1: South | CU1: South | CV1: South | CW1: South | CX1: South | CY1: South | CZ1: South | DA1: South | DB1: South | DC1: South | DD1: South | DE1: South | DF1: South | DG1: South | DH1: South | DI1: South | DJ1: South | DK1: South | DL1: South | DM1: South
R2: 2020 | S2: vs | T2: 2026 | X2: 2020 | Y2: vs | Z2: 2026 | AD2: 2020 | AE2: vs | AF2: 2026 | AK2: 2020 | AL2: vs | AM2: 2026 | AR2: 2020 | AS2: vs | AT2: 2026 | AY2: 2020 | AZ2: vs | BA2: 2026 | BU2: SATL | BV2: 2022 | BW2: vs | BX2: 2026 | CD2: 2022 | CE2: vs | CF2: 2026 | CJ2: 2022 | CK2: vs | CL2: 2026 | CP2: 2022 | CQ2: vs | CR2: 2026
R3: Compare GRC LL index | X3: Compare n_SPN LL index | AD3: Compare w_SPN LL index | AK3: Compare w_LIG_LL | AR3: Compare n_LIG_LL | AY3: Compare MOR LL index
A4: stock, med and south | R4: scaled to overlap years | X4: scaled to overlap years | AD4: scaled to overlap years
AN5: scaled to overlap years | AU5: scaled to overlap years | BB5: scaled to overlap years | BV5: BRA LL | BW5: BRA-URY LL | CD5: w SPN LL | CJ5: n SPN LL | CP5: ZAF LL | CX5: JPNLL | CY5: JPNLL | CZ5: JPNLL | DJ5: CTPLL
R6: Year | S6: 2020 | T6: 2026 | U6: =+S6 -> 2020 | V6: =+T6 -> 2026 | X6: Year | Y6: 2020 | Z6: 2026 | AA6: =+Y6 -> 2020 | AB6: =+Z6 -> 2026 | AD6: Year | AE6: 2020 | AF6: 2026 | AG6: =+AE6 -> 2020 | AH6: =+AF6 -> 2026 | AK6: Year | AL6: 2020 | AM6: 2026 | AN6: =+AL6 -> 2020 | AO6: =+AM6 -> 2026 | AR6: Year | AS6: 2020 | AT6: 2026 | AU6: =+AS6 -> 2020 | AV6: =+AT6 -> 2026 | AY6: Year | AZ6: 2020 | BA6: 2026 | BB6: =+AZ6 -> 2020 | BC6: =+BA6 -> 2026 | BV6: 2022 BRALL | BW6: 2026 BRA-URY LL novessel | BX6: 2026 BRA-URY LL w_vessel | BY6: 2022 BRALL | BZ6: 2026 BRA-URY LL novessel | CA6: 2026 BRA-URY LL w_vessel | CD6: 2022 | CE6: 2026 | CF6: =+CD6 -> 2022 | CG6: =+CE6 -> 2026 | CJ6: 2022 | CK6: 2026 | CL6: =+CJ6 -> 2022 | CM6: =+CK6 -> 2026 | CP6: 2022 | CQ6: 2026 | CR6: 2022 | CS6: 2026 | CV6: JPNLL1_2022 | CW6: JPNLL2_2022 | CX6: JPNLL1_2026 | CY6: JPNLL2_2026 | CZ6: JPNLL3_2026 | DA6: =+CV6 -> JPNLL1_2022 | DB6: =+CW6 -> JPNLL2_2022 | DC6: =+CX6 -> JPNLL1_2026 | DD6: =+CY6 -> JPNLL2_2026 | DE6: =+CZ6 -> JPNLL3_2026 | DH6: CTPLL1_2022 | DI6: CTPLL2_2022 | DJ6: 2026 | DK6: =+DH6 -> CTPLL1_2022 | DL6: =+DI6 -> CTPLL2_2022 | DM6: =+DJ6 -> 2026 | DR6: atDP | DS6: afterDP | DT6: atDP | DU6: afterDP
R7: 1987 | S7: 214.7 | T7: 181.7 | U7: =+S7/S$46 -> 1.3580013 | V7: =+T7/T$46 -> 1.0400538 | X7: 1987 | AD7: 1987 | AK7: 2010 | AL7: 332.03 | AM7: 336.73 | AN7: =+AL7/AL$23 -> 1.8555958 | AO7: =+AM7/AM$23 -> 1.6699656 | AR7: 2010 | AS7: 7.95 | AT7: 8.95 | AU7: =+AS7/AS$23 -> 1.3818076 | AV7: =+AT7/AT$23 -> 1.3021339 | AY7: 2012 | AZ7: 276.912 | BA7: 111.2 | BB7: =+AZ7/AZ$23 -> 1.9259041 | BC7: =+BA7/BA$23 -> 1.2147809 | BU7: 1994 | BV7: 1.052 | BW7: 1.094 | BX7: 0.915 | BY7: =+BV7/BV$40 -> 1.0245644 | BZ7: =+BW7/BW$40 -> 1.0229256 | CA7: =+BX7/BX$40 -> 0.81394966 | CC7: 1989 | CD7: 522.857 | CE7: 583.153 | CF7: =+CD7/CD$45 -> 1.3518738 | CG7: =+CE7/CE$45 -> 1.283133 | CI7: 1989 | CJ7: 9.45886 | CK7: 9.6328 | CL7: =+CJ7/CJ$45 -> 1.2426306 | CM7: =+CK7/CK$45 -> 1.1340311 | CO7: 2004 | CP7: 541.83997 | CQ7: 1.25 | CR7: =+CP7/CP$30 -> 1.5294435 | CS7: =+CQ7/CQ$30 -> 1.1727373 | CU7: 1962 | CX7: 2.5 | DC7: =+CX7/CX$71 -> 2.5035765 | DG7: 1962 | DQ7: 1994 | DR7: 9.678401 | DS7: 9.320395 | DT7: =+DR7/AVERAGE(DR$7:DR$37) -> 1.4913266 | DU7: =+DS7/AVERAGE(DS$7:DS$37) -> 1.4377266
R8: 1988 | S8: 238.2 | T8: 213.31 | U8: =+S8/S$46 -> 1.5066414 | V8: =+T8/T$46 -> 1.22099 | X8: 1988 | Y8: 3.3970693 | Z8: 11.7582 | AA8: =+Y8/Y$46 -> 1.1922943 | AB8: =+Z8/Z$46 -> 1.6763384 | AD8: 1988 | AE8: 127.7592 | AF8: 128.575 | AG8: =+AE8/AE$46 -> 1.2582017 | AH8: =+AF8/AF$46 -> 1.2728399 | AK8: =1+AK7 -> 2011 | AL8: 239 | AM8: 246.91 | AN8: =+AL8/AL$23 -> 1.3356847 | AO8: =+AM8/AM$23 -> 1.2245158 | AR8: =1+AR7 -> 2011 | AS8: 7.17 | AT8: 7.69 | AU8: =+AS8/AS$23 -> 1.2462341 | AV8: =+AT8/AT$23 -> 1.1188167 | AY8: =1+AY7 -> 2013 | AZ8: 164.003 | BA8: 155.757 | BB8: =+AZ8/AZ$23 -> 1.1406297 | BC8: =+BA8/BA$23 -> 1.7015344 | BU8: 1995 | BV8: 1.436 | BW8: 1.425 | BX8: 1.262 | BY8: =+BV8/BV$40 -> 1.3985499 | BZ8: =+BW8/BW$40 -> 1.3324214 | CA8: =+BX8/BX$40 -> 1.1226278 | CC8: 1990 | CD8: 396.324 | CE8: 439.132 | CF8: =+CD8/CD$45 -> 1.0247162 | CG8: =+CE8/CE$45 -> 0.96623832 | CI8: 1990 | CJ8: 6.94712 | CK8: 7.2861 | CL8: =+CJ8/CJ$45 -> 0.912658 | CM8: =+CK8/CK$45 -> 0.85776344 | CO8: 2005 | CP8: 465.70948 | CQ8: 1.95 | CR8: =+CP8/CP$30 -> 1.3145511 | CS8: =+CQ8/CQ$30 -> 1.8294702 | CU8: =+CU7+1 -> 1963 | CX8: 1.9 | DC8: =+CX8/CX$71 -> 1.9027182 | DG8: =+DG7+1 -> 1963 | DQ8: 1995 | DR8: 8.4363388 | DS8: 8.220347 | DT8: =+DR8/AVERAGE(DR$7:DR$37) -> 1.2999396 | DU8: =+DS8/AVERAGE(DS$7:DS$37) -> 1.2680376
R9: 1989 | T9: 247.25 | V9: =+T9/T$46 -> 1.4152631 | X9: 1989 | Y9: 2.3286833 | Z9: 4.1086 | AA9: =+Y9/Y$46 -> 0.81731506 | AB9: =+Z9/Z$46 -> 0.58575327 | AD9: 1989 | AE9: 115.50113 | AF9: 115.4062 | AG9: =+AE9/AE$46 -> 1.1374814 | AH9: =+AF9/AF$46 -> 1.1424741 | AK9: =1+AK8 -> 2012 | AL9: 143.5 | AM9: 156.27 | AN9: =+AL9/AL$23 -> 0.80196968 | AO9: =+AM9/AM$23 -> 0.77499931 | AR9: =1+AR8 -> 2012 | AS9: 5.29 | AT9: 6.08 | AU9: =+AS9/AS$23 -> 0.91946698 | AV9: =+AT9/AT$23 -> 0.88457808 | AY9: =1+AY8 -> 2014 | AZ9: 190.499 | BA9: 77.266 | BB9: =+AZ9/AZ$23 -> 1.3249076 | BC9: =+BA9/BA$23 -> 0.84407607 | BU9: 1996 | BV9: 1.581 | BW9: 1.726 | BX9: 1.216 | BY9: =+BV9/BV$40 -> 1.5397684 | BZ9: =+BW9/BW$40 -> 1.6138662 | CA9: =+BX9/BX$40 -> 1.081708 | CC9: 1991 | CD9: 384.849 | CE9: 428.029 | CF9: =+CD9/CD$45 -> 0.995047 | CG9: =+CE9/CE$45 -> 0.94180798 | CI9: 1991 | CJ9: 7.01862 | CK9: 7.4092 | CL9: =+CJ9/CJ$45 -> 0.92205111 | CM9: =+CK9/CK$45 -> 0.87225551 | CO9: 2006 | CP9: 396.89674 | CQ9: 1.49 | CR9: =+CP9/CP$30 -> 1.1203144 | CS9: =+CQ9/CQ$30 -> 1.3979029 | CU9: =+CU8+1 -> 1964 | CX9: 1.7 | DC9: =+CX9/CX$71 -> 1.702432 | DG9: =+DG8+1 -> 1964 | DQ9: 1996 | DR9: 9.1710564 | DS9: 8.762103 | DT9: =+DR9/AVERAGE(DR$7:DR$37) -> 1.4131508 | DU9: =+DS9/AVERAGE(DS$7:DS$37) -> 1.3516067
R10: 1990 | S10: 234.5 | T10: 186.44 | U10: =+S10/S$46 -> 1.4832385 | V10: =+T10/T$46 -> 1.0671856 | X10: 1990 | Y10: 2.4615767 | Z10: 4.6593 | AA10: =+Y10/Y$46 -> 0.86395761 | AB10: =+Z10/Z$46 -> 0.66426525 | AD10: 1990 | AE10: 124.55557 | AF10: 122.1755 | AG10: =+AE10/AE$46 -> 1.2266517 | AH10: =+AF10/AF$46 -> 1.2094874 | AK10: =1+AK9 -> 2013 | AL10: 158.52 | AM10: 171.67 | AN10: =+AL10/AL$23 -> 0.88591104 | AO10: =+AM10/AM$23 -> 0.85137347 | AR10: =1+AR9 -> 2013 | AS10: 5.03 | AT10: 5.9 | AU10: =+AS10/AS$23 -> 0.87427578 | AV10: =+AT10/AT$23 -> 0.85838991 | AY10: =1+AY9 -> 2015 | AZ10: 156.778 | BA10: 88.18 | BB10: =+AZ10/AZ$23 -> 1.0903803 | BC10: =+BA10/BA$23 -> 0.96330375 | BU10: 1997 | BV10: 1.492 | BW10: 1.605 | BX10: 1.191 | BY10: =+BV10/BV$40 -> 1.4530895 | BZ10: =+BW10/BW$40 -> 1.5007272 | CA10: =+BX10/BX$40 -> 1.0594689 | CC10: 1992 | CD10: 349.279 | CE10: 386.308 | CF10: =+CD10/CD$45 -> 0.90307893 | CG10: =+CE10/CE$45 -> 0.85000772 | CI10: 1992 | CJ10: 6.34249 | CK10: 6.6774 | CL10: =+CJ10/CJ$45 -> 0.83322646 | CM10: =+CK10/CK$45 -> 0.78610362 | CO10: 2007 | CP10: 387.23407 | CQ10: 1.36 | CR10: =+CP10/CP$30 -> 1.0930398 | CS10: =+CQ10/CQ$30 -> 1.2759382 | CU10: =+CU9+1 -> 1965 | CX10: 1.2 | DC10: =+CX10/CX$71 -> 1.2017167 | DG10: =+DG9+1 -> 1965 | DQ10: 1997 | DR10: 7.5944379 | DS10: 7.366469 | DT10: =+DR10/AVERAGE(DR$7:DR$37) -> 1.1702127 | DU10: =+DS10/AVERAGE(DS$7:DS$37) -> 1.1363218
R11: 1991 | S11: 316.8 | T11: 228.97 | U11: =+S11/S$46 -> 2.0037951 | V11: =+T11/T$46 -> 1.3106281 | X11: 1991 | Y11: 2.9209263 | Z11: 7.3097 | AA11: =+Y11/Y$46 -> 1.0251789 | AB11: =+Z11/Z$46 -> 1.0421264 | AD11: 1991 | AE11: 85.883965 | AF11: 86.7179 | AG11: =+AE11/AE$46 -> 0.84580485 | AH11: =+AF11/AF$46 -> 0.85847172 | AK11: =1+AK10 -> 2014 | AL11: 224.52 | AM11: 245.33 | AN11: =+AL11/AL$23 -> 1.2547612 | AO11: =+AM11/AM$23 -> 1.21668 | AR11: =1+AR10 -> 2014 | AS11: 8.01 | AT11: 9.6 | AU11: =+AS11/AS$23 -> 1.3922364 | AV11: =+AT11/AT$23 -> 1.3967022 | AY11: =1+AY10 -> 2016 | AZ11: 58.971 | BA11: 87.318 | BB11: =+AZ11/AZ$23 -> 0.4101393 | BC11: =+BA11/BA$23 -> 0.95388702 | BU11: 1998 | BV11: 1.261 | BW11: 1.347 | BX11: 1.249 | BY11: =+BV11/BV$40 -> 1.2281138 | BZ11: =+BW11/BW$40 -> 1.2594888 | CA11: =+BX11/BX$40 -> 1.1110635 | CC11: 1993 | CD11: 302.03 | CE11: 331.888 | CF11: =+CD11/CD$45 -> 0.78091419 | CG11: =+CE11/CE$45 -> 0.73026539 | CI11: 1993 | CJ11: 5.71652 | CK11: 6.0407 | CL11: =+CJ11/CJ$45 -> 0.75099145 | CM11: =+CK11/CK$45 -> 0.71114748 | CO11: 2008 | CP11: 324.82878 | CQ11: 0.92 | CR11: =+CP11/CP$30 -> 0.91688931 | CS11: =+CQ11/CQ$30 -> 0.86313466 | CU11: =+CU10+1 -> 1966 | CX11: 0.91 | DC11: =+CX11/CX$71 -> 0.91130186 | DG11: =+DG10+1 -> 1966 | DQ11: 1998 | DR11: 8.7230603 | DS11: 8.628698 | DT11: =+DR11/AVERAGE(DR$7:DR$37) -> 1.34412 | DU11: =+DS11/AVERAGE(DS$7:DS$37) -> 1.3310282
R12: 1992 | S12: 127.4 | T12: 100.21 | U12: =+S12/S$46 -> 0.8058191 | V12: =+T12/T$46 -> 0.5736037 | X12: 1992 | Y12: 3.0472063 | Z12: 8.2662 | AA12: =+Y12/Y$46 -> 1.0695003 | AB12: =+Z12/Z$46 -> 1.1784923 | AD12: 1992 | AE12: 74.20049 | AF12: 74.2483 | AG12: =+AE12/AE$46 -> 0.73074333 | AH12: =+AF12/AF$46 -> 0.73502778 | AK12: =1+AK11 -> 2015 | AL12: 160.05 | AM12: 158.99 | AN12: =+AL12/AL$23 -> 0.89446166 | AO12: =+AM12/AM$23 -> 0.78848877 | AR12: =1+AR11 -> 2015 | AS12: 5.14 | AT12: 5.36 | AU12: =+AS12/AS$23 -> 0.89339513 | AV12: =+AT12/AT$23 -> 0.77982541 | AY12: =1+AY11 -> 2017 | AZ12: 67.877 | BA12: 57.424 | BB12: =+AZ12/AZ$23 -> 0.47207992 | BC12: =+BA12/BA$23 -> 0.62731634 | BU12: 1999 | BV12: 1.056 | BW12: 1.05 | BX12: 1.032 | BY12: =+BV12/BV$40 -> 1.0284601 | BZ12: =+BW12/BW$40 -> 0.98178418 | CA12: =+BX12/BX$40 -> 0.91802847 | CC12: 1994 | CD12: 345.977 | CE12: 383.892 | CF12: =+CD12/CD$45 -> 0.89454143 | CG12: =+CE12/CE$45 -> 0.84469171 | CI12: 1994 | CJ12: 6.93133 | CK12: 7.3698 | CL12: =+CJ12/CJ$45 -> 0.91058363 | CM12: =+CK12/CK$45 -> 0.86761711 | CO12: 2009 | CP12: 314.95114 | CQ12: 0.85 | CR12: =+CP12/CP$30 -> 0.88900786 | CS12: =+CQ12/CQ$30 -> 0.79746137 | CU12: =+CU11+1 -> 1967 | CX12: 0.46 | DC12: =+CX12/CX$71 -> 0.46065808 | DG12: =+DG11+1 -> 1967 | DQ12: 1999 | DR12: 6.1909225 | DS12: 6.114747 | DT12: =+DR12/AVERAGE(DR$7:DR$37) -> 0.9539476 | DU12: =+DS12/AVERAGE(DS$7:DS$37) -> 0.94323625
R13: 1993 | S13: 211.4 | T13: 151.64 | U13: =+S13/S$46 -> 1.3371284 | V13: =+T13/T$46 -> 0.86798987 | X13: 1993 | Y13: 3.0430707 | Z13: 8.2301 | AA13: =+Y13/Y$46 -> 1.0680488 | AB13: =+Z13/Z$46 -> 1.1733457 | AD13: 1993 | AE13: 98.336918 | AF13: 98.0339 | AG13: =+AE13/AE$46 -> 0.96844438 | AH13: =+AF13/AF$46 -> 0.97049548 | AK13: =1+AK12 -> 2016 | AL13: 145.51 | AM13: 197.82 | AN13: =+AL13/AL$23 -> 0.81320285 | AO13: =+AM13/AM$23 -> 0.98106075 | AR13: =1+AR12 -> 2016 | AS13: 5.62 | AT13: 7.7 | AU13: =+AS13/AS$23 -> 0.97682503 | AV13: =+AT13/AT$23 -> 1.1202716 | AY13: =1+AY12 -> 2018 | AZ13: 91.44 | BA13: 63.629 | BB13: =+AZ13/AZ$23 -> 0.63595899 | BC13: =+BA13/BA$23 -> 0.69510155 | BU13: 2000 | BV13: 0.948 | BW13: 0.96 | BX13: 1.042 | BY13: =+BV13/BV$40 -> 0.9232767 | BZ13: =+BW13/BW$40 -> 0.89763125 | CA13: =+BX13/BX$40 -> 0.92692409 | CC13: 1995 | CD13: 395.588 | CE13: 438.518 | CF13: =+CD13/CD$45 -> 1.0228132 | CG13: =+CE13/CE$45 -> 0.96488731 | CI13: 1995 | CJ13: 8.18962 | CK13: 8.6717 | CL13: =+CJ13/CJ$45 -> 1.0758879 | CM13: =+CK13/CK$45 -> 1.0208846 | CO13: 2010 | CP13: 355.08458 | CQ13: 1.27 | CR13: =+CP13/CP$30 -> 1.0022919 | CS13: =+CQ13/CQ$30 -> 1.1915011 | CU13: =+CU12+1 -> 1968 | CX13: 0.8 | DC13: =+CX13/CX$71 -> 0.80114449 | DG13: =+DG12+1 -> 1968 | DH13: 0.091082152 | DK13: =+DH13/DH$71 -> 1.1968739 | DQ13: 2000 | DR13: 7.0119783 | DS13: 6.895216 | DT13: =+DR13/AVERAGE(DR$7:DR$37) -> 1.0804625 | DU13: =+DS13/AVERAGE(DS$7:DS$37) -> 1.0636283
R14: 1994 | S14: 298.4 | T14: 175.7 | U14: =+S14/S$46 -> 1.887413 | V14: =+T14/T$46 -> 1.0057097 | X14: 1994 | Y14: 3.2752519 | Z14: 10.362 | AA14: =+Y14/Y$46 -> 1.1495392 | AB14: =+Z14/Z$46 -> 1.4772855 | AD14: 1994 | AE14: 120.48191 | AF14: 119.9387 | AG14: =+AE14/AE$46 -> 1.1865333 | AH14: =+AF14/AF$46 -> 1.187344 | AK14: =1+AK13 -> 2017 | AL14: 118.75 | AM14: 179.97 | AN14: =+AL14/AL$23 -> 0.66365087 | AO14: =+AM14/AM$23 -> 0.89253616 | AR14: =1+AR13 -> 2017 | AS14: 4.19 | AT14: 6.46 | AU14: =+AS14/AS$23 -> 0.72827346 | AV14: =+AT14/AT$23 -> 0.93986421 | AY14: =1+AY13 -> 2019 | BA14: 47.145 | BC14: =+BA14/BA$23 -> 0.51502558 | BU14: 2001 | BV14: 0.884 | BW14: 0.849 | BX14: 0.93 | BY14: =+BV14/BV$40 -> 0.86094579 | BZ14: =+BW14/BW$40 -> 0.79384264 | CA14: =+BX14/BX$40 -> 0.82729309 | CC14: 1996 | CD14: 355.344 | CE14: 389.464 | CF14: =+CD14/CD$45 -> 0.9187603 | CG14: =+CE14/CE$45 -> 0.85695199 | CI14: 1996 | CJ14: 7.2182 | CK14: 7.5809 | CL14: =+CJ14/CJ$45 -> 0.94827036 | CM14: =+CK14/CK$45 -> 0.89246907 | CO14: 2011 | CP14: 239.92991 | CQ14: 0.61 | CR14: =+CP14/CP$30 -> 0.67724655 | CS14: =+CQ14/CQ$30 -> 0.57229581 | CU14: =+CU13+1 -> 1969 | CX14: 0.86 | DC14: =+CX14/CX$71 -> 0.86123033 | DG14: =+DG13+1 -> 1969 | DH14: 0.066517906 | DK14: =+DH14/DH$71 -> 0.87408503 | DQ14: 2001 | DR14: 6.250734 | DS14: 6.172336 | DT14: =+DR14/AVERAGE(DR$7:DR$37) -> 0.96316384 | DU14: =+DS14/AVERAGE(DS$7:DS$37) -> 0.9521197
