Workbook

Sheet Indices
C1: 1999-2011 | D1: 1988-2015 | E1: 2001-2015 | F1: 1991-2009 | G1: 1990-2009 | H1: 1987-2015 | I1: 1991-2009
A2: SCRS paper
A3: Country/Location | C3: Morocco | D3: Spain | E3: Morocco | F3: Sicily | G3: Sicily | H3: Greece | I3: Liguria
A4: Gear | C4: Gillnet | D4: Longline | E4: Longline | F4: Longline | G4: Gillnet | H4: Longline | I4: Longline | P4: Indices scaled to the mean
A5: Used in assessment | C5: yes | D5: yes | E5: no | F5: yes | G5: yes | H5: yes | I5: yes
A6: Identifier | C6: MoGN | D6: SpLL | E6: MoLL | F6: SiLL | G6: SiGN | H6: GrLL | I6: LiLL | M6: Year | N6: MoGN | O6: SpLL | P6: MoLL | Q6: SiLL | R6: SiGN | S6: GrLL | T6: LiLL
B7: 1987 | H7: =SicilyGreece!C3 -> 184.62 | M7: 1987 | S7: =H7/H$37 -> 1.2810016
B8: 1988 | D8: ='Spanish LL'!B5 -> 2.48 | H8: =SicilyGreece!C4 -> 220.85 | M8: 1988 | O8: =D8/D$37 -> 1.2790569 | S8: =H8/H$37 -> 1.5323865
B9: 1989 | D9: ='Spanish LL'!B6 -> 1.43 | M9: 1989 | O9: =D9/D$37 -> 0.73752072
B10: 1990 | D10: ='Spanish LL'!B7 -> 1.56 | G10: 8.31 | H10: =SicilyGreece!C6 -> 202.21 | M10: 1990 | O10: =D10/D$37 -> 0.80456806 | R10: =G10/G$37 -> 0.67412674 | S10: =H10/H$37 -> 1.4030513
B11: 1991 | D11: ='Spanish LL'!B8 -> 2.02 | F11: =SicilyGreece!D7 -> 100.28498 | G11: 9.8 | H11: =SicilyGreece!C7 -> 273.55 | I11: =SicilyGreece!B7 -> 88.467336 | M11: 1991 | O11: =D11/D$37 -> 1.0418125 | Q11: =F11/F$37 -> 0.87697281 | R11: =G11/G$37 -> 0.79499905 | S11: =H11/H$37 -> 1.89805 | T11: =I11/I$37 -> 0.71956447
B12: 1992 | D12: ='Spanish LL'!B9 -> 2.13 | F12: =SicilyGreece!D8 -> 98.514928 | G12: 16.87 | H12: =SicilyGreece!C8 -> 105.92 | I12: =SicilyGreece!B8 -> 66.100051 | M12: 1992 | O12: =D12/D$37 -> 1.0985449 | Q12: =F12/F$37 -> 0.86149401 | R12: =G12/G$37 -> 1.3685341 | S12: =H12/H$37 -> 0.73493494 | T12: =I12/I$37 -> 0.53763626
B13: 1993 | D13: ='Spanish LL'!B10 -> 2.12 | G13: 13.04 | H13: =SicilyGreece!C9 -> 186.92 | I13: =SicilyGreece!B9 -> 68.763321 | M13: 1993 | O13: =D13/D$37 -> 1.0933874 | R13: =G13/G$37 -> 1.0578355 | S13: =H13/H$37 -> 1.2969603 | T13: =I13/I$37 -> 0.55929843
B14: 1994 | D14: ='Spanish LL'!B11 -> 2.36 | F14: =SicilyGreece!D10 -> 99.454398 | G14: 9.49 | H14: =SicilyGreece!C10 -> 238.65 | I14: =SicilyGreece!B10 -> 90.595943 | M14: 1994 | O14: =D14/D$37 -> 1.2171671 | Q14: =F14/F$37 -> 0.86970949 | R14: =G14/G$37 -> 0.76985112 | S14: =H14/H$37 -> 1.6558934 | T14: =I14/I$37 -> 0.73687787
B15: 1995 | D15: ='Spanish LL'!B12 -> 2.2 | F15: =SicilyGreece!D11 -> 124.19214 | G15: 14.65 | H15: =SicilyGreece!C11 -> 156.12 | I15: =SicilyGreece!B11 -> 94.617415 | M15: 1995 | O15: =D15/D$37 -> 1.1346473 | Q15: =F15/F$37 -> 1.0860363 | R15: =G15/G$37 -> 1.1884425 | S15: =H15/H$37 -> 1.0832519 | T15: =I15/I$37 -> 0.7695872
B16: 1996 | D16: ='Spanish LL'!B13 -> 1.82 | G16: 9.33 | I16: =SicilyGreece!B12 -> 94.344342 | M16: 1996 | O16: =D16/D$37 -> 0.93866274 | R16: =G16/G$37 -> 0.75687154 | T16: =I16/I$37 -> 0.76736611
B17: 1997 | D17: ='Spanish LL'!B14 -> 1.78 | F17: =SicilyGreece!D13 -> 75.917216 | G17: 14.04 | I17: =SicilyGreece!B13 -> 101.06904 | M17: 1997 | O17: =D17/D$37 -> 0.91803279 | Q17: =F17/F$37 -> 0.66388139 | R17: =G17/G$37 -> 1.1389578 | T17: =I17/I$37 -> 0.82206263
B18: 1998 | D18: ='Spanish LL'!B15 -> 1.98 | F18: =SicilyGreece!D14 -> 127.62963 | G18: 10.12 | H18: =SicilyGreece!C14 -> 227.28 | I18: =SicilyGreece!B14 -> 144.93701 | M18: 1998 | O18: =D18/D$37 -> 1.0211825 | Q18: =F18/F$37 -> 1.1160964 | R18: =G18/G$37 -> 0.8209582 | S18: =H18/H$37 -> 1.5770016 | T18: =I18/I$37 -> 1.1788704
B19: 1999 | C19: =MoroccoGN!B3 -> 58.256 | D19: ='Spanish LL'!B16 -> 1.73 | F19: =SicilyGreece!D15 -> 151.49775 | G19: 12.71 | H19: =SicilyGreece!C15 -> 157.7 | I19: =SicilyGreece!B15 -> 101.89597 | M19: 1999 | N19: =C19/C$37 -> 1.0046017 | O19: =D19/D$37 -> 0.89224535 | Q19: =F19/F$37 -> 1.3248186 | R19: =G19/G$37 -> 1.0310651 | S19: =H19/H$37 -> 1.0942149 | T19: =I19/I$37 -> 0.82878861
B20: 2000 | C20: =MoroccoGN!B4 -> 66.671 | D20: ='Spanish LL'!B17 -> 1.55 | F20: =SicilyGreece!D16 -> 93.349615 | G20: 14.92 | H20: =SicilyGreece!C16 -> 112.5 | I20: =SicilyGreece!B16 -> 134.68065 | M20: 2000 | N20: =C20/C$37 -> 1.149715 | O20: =D20/D$37 -> 0.79941057 | Q20: =F20/F$37 -> 0.81632435 | R20: =G20/G$37 -> 1.2103455 | S20: =H20/H$37 -> 0.78059083 | T20: =I20/I$37 -> 1.0954485
B21: 2001 | C21: =MoroccoGN!B5 -> 43.149 | D21: ='Spanish LL'!B18 -> 1.83 | E21: =MoroccoLL!B2 -> 26.4668 | F21: =SicilyGreece!D17 -> 143.95968 | G21: 13.06 | H21: =SicilyGreece!C17 -> 117.49 | I21: =SicilyGreece!B17 -> 181.62454 | K21: ` | M21: 2001 | N21: =C21/C$37 -> 0.74408742 | O21: =D21/D$37 -> 0.94382022 | P21: =E21/E$37 -> 0.59660066 | Q21: =F21/F$37 -> 1.2588996 | R21: =G21/G$37 -> 1.0594579 | S21: =H21/H$37 -> 0.81521437 | T21: =I21/I$37 -> 1.4772748
B22: 2002 | C22: =MoroccoGN!B6 -> 56.034 | D22: ='Spanish LL'!B19 -> 2.45 | E22: =MoroccoLL!B3 -> 31.8979 | F22: =SicilyGreece!D18 -> 204.83786 | H22: =SicilyGreece!C18 -> 95.68 | I22: =SicilyGreece!B18 -> 140.32481 | M22: 2002 | N22: =C22/C$37 -> 0.96628415 | O22: =D22/D$37 -> 1.2635845 | P22: =E22/E$37 -> 0.71902565 | Q22: =F22/F$37 -> 1.7912675 | S22: =H22/H$37 -> 0.66388383 | T22: =I22/I$37 -> 1.1413563
B23: 2003 | C23: =MoroccoGN!B7 -> 48.181 | D23: ='Spanish LL'!B20 -> 1.96 | E23: =MoroccoLL!B4 -> 36.0351 | F23: =SicilyGreece!D19 -> 82.223803 | H23: =SicilyGreece!C19 -> 115.3 | I23: =SicilyGreece!B19 -> 152.27809 | M23: 2003 | N23: =C23/C$37 -> 0.83086227 | O23: =D23/D$37 -> 1.0108676 | P23: =E23/E$37 -> 0.81228423 | Q23: =F23/F$37 -> 0.71903127 | S23: =H23/H$37 -> 0.80001887 | T23: =I23/I$37 -> 1.2385803
B24: 2004 | C24: =MoroccoGN!B8 -> 58.411 | D24: ='Spanish LL'!B21 -> 1.65 | E24: =MoroccoLL!B5 -> 38.6269 | F24: =SicilyGreece!D20 -> 111.18542 | G24: 15.15 | H24: =SicilyGreece!C20 -> 115.75 | I24: =SicilyGreece!B20 -> 98.857786 | M24: 2004 | N24: =C24/C$37 -> 1.0072746 | O24: =D24/D$37 -> 0.85098545 | P24: =E24/E$37 -> 0.87070722 | Q24: =F24/F$37 -> 0.97229502 | R24: =G24/G$37 -> 1.2290036 | S24: =H24/H$37 -> 0.80314124 | T24: =I24/I$37 -> 0.804077
B25: 2005 | C25: =MoroccoGN!B9 -> 70.678 | D25: ='Spanish LL'!B22 -> 1.87 | E25: =MoroccoLL!B6 -> 30.4991 | F25: =SicilyGreece!D21 -> 123.21227 | G25: 12.07 | H25: =SicilyGreece!C21 -> 114.65 | I25: =SicilyGreece!B21 -> 80.801294 | M25: 2005 | N25: =C25/C$37 -> 1.2188141 | O25: =D25/D$37 -> 0.96445017 | P25: =E25/E$37 -> 0.68749464 | Q25: =F25/F$37 -> 1.0774675 | R25: =G25/G$37 -> 0.97914678 | S25: =H25/H$37 -> 0.79550879 | T25: =I25/I$37 -> 0.65721138
B26: 2006 | C26: =MoroccoGN!B10 -> 66.164 | D26: ='Spanish LL'!B23 -> 1.98 | E26: =MoroccoLL!B7 -> 43.9984 | F26: =SicilyGreece!D22 -> 140.62136 | G26: 30.74 | H26: =SicilyGreece!C22 -> 123.44 | I26: =SicilyGreece!B22 -> 125.04794 | M26: 2006 | N26: =C26/C$37 -> 1.140972 | O26: =D26/D$37 -> 1.0211825 | P26: =E26/E$37 -> 0.99178874 | Q26: =F26/F$37 -> 1.2297067 | R26: =G26/G$37 -> 2.4937011 | S26: =H26/H$37 -> 0.85649896 | T26: =I26/I$37 -> 1.0170992
B27: 2007 | C27: =MoroccoGN!B11 -> 63.163 | D27: ='Spanish LL'!B24 -> 2.24 | E27: =MoroccoLL!B8 -> 41.2178 | F27: =SicilyGreece!D23 -> 81.060357 | H27: =SicilyGreece!C23 -> 127.24 | I27: =SicilyGreece!B23 -> 239.99924 | M27: 2007 | N27: =C27/C$37 -> 1.0892209 | O27: =D27/D$37 -> 1.1552772 | P27: =E27/E$37 -> 0.92910992 | Q27: =F27/F$37 -> 0.70885716 | S27: =H27/H$37 -> 0.88286558 | T27: =I27/I$37 -> 1.9520756
B28: 2008 | C28: =MoroccoGN!B12 -> 69.178 | D28: ='Spanish LL'!B25 -> 2.16 | E28: =MoroccoLL!B9 -> 33.106 | F28: =SicilyGreece!D24 -> 86.951489 | G28: 3.29 | H28: =SicilyGreece!C24 -> 122.51 | I28: =SicilyGreece!B24 -> 208.17563 | M28: 2008 | N28: =C28/C$37 -> 1.1929472 | O28: =D28/D$37 -> 1.1140173 | P28: =E28/E$37 -> 0.746258 | Q28: =F28/F$37 -> 0.76037397 | R28: =G28/G$37 -> 0.26689254 | S28: =H28/H$37 -> 0.85004607 | T28: =I28/I$37 -> 1.6932327
B29: 2009 | C29: =MoroccoGN!B13 -> 55.582 | D29: ='Spanish LL'!B26 -> 1.59 | E29: =MoroccoLL!B10 -> 34.469 | F29: =SicilyGreece!D25 -> 99.118032 | G29: 1.97 | H29: =SicilyGreece!C25 -> 104.48 | I29: =SicilyGreece!B25 -> 123.38733 | M29: 2009 | N29: =C29/C$37 -> 0.95848958 | O29: =D29/D$37 -> 0.82004052 | P29: =E29/E$37 -> 0.77698203 | Q29: =F29/F$37 -> 0.86676804 | R29: =G29/G$37 -> 0.15981103 | S29: =H29/H$37 -> 0.72494338 | T29: =I29/I$37 -> 1.0035923
B30: 2010 | C30: =MoroccoGN!B14 -> 51.887 | D30: ='Spanish LL'!B27 -> 1.71 | E30: =MoroccoLL!B11 -> 34.5673 | H30: =SicilyGreece!C26 -> 126.8 | M30: 2010 | N30: =C30/C$37 -> 0.89477077 | O30: =D30/D$37 -> 0.88193037 | P30: =E30/E$37 -> 0.77919786 | S30: =H30/H$37 -> 0.8798126
B31: 2011 | C31: =MoroccoGN!B15 -> 46.505 | D31: ='Spanish LL'!B28 -> 1.82 | E31: =MoroccoLL!B12 -> 40.1586 | H31: =SicilyGreece!C27 -> 99.11 | M31: 2011 | N31: =C31/C$37 -> 0.80196031 | O31: =D31/D$37 -> 0.93866274 | P31: =E31/E$37 -> 0.90523399 | S31: =H31/H$37 -> 0.68768318
B32: 2012 | D32: ='Spanish LL'!B29 -> 2.13 | E32: =MoroccoLL!B13 -> 72.7279 | H32: =SicilyGreece!C28 -> 97.5 | M32: 2012 | O32: =D32/D$37 -> 1.0985449 | P32: =E32/E$37 -> 1.639394 | S32: =H32/H$37 -> 0.67651206
B33: 2013 | D33: ='Spanish LL'!B30 -> 1.89 | E33: =MoroccoLL!B14 -> 70.8365 | H33: =SicilyGreece!C29 -> 149.78 | M33: 2013 | O33: =D33/D$37 -> 0.97476515 | P33: =E33/E$37 -> 1.596759 | S33: =H33/H$37 -> 1.0392613
B34: 2014 | D34: ='Spanish LL'!B31 -> 1.92 | E34: =MoroccoLL!B15 -> 63.5715 | H34: =SicilyGreece!C30 -> 115.06 | M34: 2014 | O34: =D34/D$37 -> 0.99023761 | P34: =E34/E$37 -> 1.4329952 | S34: =H34/H$37 -> 0.79835361
B35: 2015 | D35: ='Spanish LL'!B32 -> 1.93 | E35: =MoroccoLL!B16 -> 67.2613 | H35: =SicilyGreece!C31 -> 96.55 | M35: 2015 | O35: =D35/D$37 -> 0.9953951 | P35: =E35/E$37 -> 1.5161688 | S35: =H35/H$37 -> 0.6699204
B37: average | C37: =AVERAGE(C7:C33) -> 57.989154 | D37: =AVERAGE(D8:D35) -> 1.9389286 | E37: =AVERAGE(E8:E35) -> 44.362673 | F37: =AVERAGE(F8:F35) -> 114.35358 | G37: =AVERAGE(G8:G35) -> 12.327059 | H37: =AVERAGE(H8:H35) -> 144.1216 | I37: =AVERAGE(I8:I35) -> 122.94567
E77: MoGN | F77: SiLL | G77: SiGN | H77: GrLL | I77: LiLL
D78: MoGN | E78: 1
D79: SpLL | E79: 0.23590385
D80: SiLL | E80: -0.20788212 | F80: 1
...

Sheet Criteria_from_2014_assessment
G1: 13 | I1: 26 | K1: 3 | M1: 6 | O1: 19 | Q1: 27
B2: TYPE OF CRITERIA
B3: Information content of data
B4: Appropriateness of method and its application
B5: Consistency of results with biology & fishery
B8: criteria not necessarily equal in importance | E8: yeaRS | G8: 1999-2011 | I8: 1988-2013 | K8: 2008-2010 | M8: 2008-2013 | O8: 1991-2009 | Q8: 1987-2013
A9: ELEMENT | B9: DESCRIPTION | C9: SUFFICIENCY SCORE (1 is poor, 3 is best) | G9: 2014/108 | I9: 2014/096 | L9: 2014/97 | O9: 2014/105 | Q9: 2014/104 | S9: Tserpes et al 2011
C10: 1 | D10: 2 | E10: 3 | G10: Gill Morocc | I10: Spain LL | K10: Gill Turkey | M10: LL Turkey | O10: Sicil LL | Q10: Greek LL | S10: Sicil GN | U10: Ligurian LL
A11: 1 | B11: Diagnostics | C11: No Diagnostics or many assumptions clearly violated | D11: Diagnostics presented but not all assumptions met | E11: Full Diagnostics and assumptions probably fully met. | G11: 2 | I11: 2 | K11: 2 | M11: 2 | O11: 2 | Q11: 2 | S11: 2 | U11: 2
A12: 2 | B12: Appropriateness of data exclusions and classifications (e.g. to identify targeted trips). | C12: Not appropriate or not sufficiently described | D12: Described but some exclusions not properly justified | E12: Fully Appropriately described and justified | G12: 3 | I12: 3 | K12: 3 | M12: 3 | O12: 3 | Q12: 3 | S12: 3 | U12: 2
A13: 3 | B13: Geographical Coverage relative to the entire distribution of the stock. | C13: Localized fishery/scientific survey, and data represents a small area within it | D13: Localized fishery but data represents all area or large fishery but data represents only part of it | E13: Fishery and data represents the major geographic range of population | G13: 2 | I13: 2 | K13: 2 | M13: 2 | O13: 2 | Q13: 2 | S13: 2 | U13: 2
A14: 4 | B14: Catch Fraction relative to the total catch of the stock. Not applicable to scientific surveys | C14: Index associated with less than 5% of the catch | D14: Index associated with between 5% and 20% of the catch | E14: Index associated with more than 20% of the catch | G14: 2 | I14: 2 | K14: 1 | M14: 1 | O14: 3 | Q14: 2 | S14: 3 | U14: 1
A15: 5 | B15: Length of Time Series relative to the history of systematic exploitation. | C15: Less than 25% of the time of exploitation (<10 years) | D15: extends between 25% and 50% of the time of exploitation (>10 years<15 years) | E15: Extends for more than 50% of the history of exploitation (>16 years) | G15: 2 | I15: 3 | K15: 1 | M15: 1 | O15: 3 | Q15: 3 | S15: 3 | U15: 3
A16: 6 | B16: Are other indices available for the same time period? | C16: More than 3 other indices available for the same period of time | D16: 1 to 3 other indices available for the same period | E16: It is the only available index for the same period of time | G16: 1 | I16: 2 | K16: 1 | M16: 1 | O16: 2 | Q16: 2 | S16: 2 | U16: 2
A17: 7 | B17: Does the index standardization account for known factors that influence catchability/selectivity? | C17: Only spatial and time factors included | D17: Some gear/vessel/technology or environmental factors included | E17: Majority of gear/vessel/technology factors included or standard scientific survey | G17: 2 | I17: 1 | K17: 1 | M17: 1 | O17: 1 | Q17: 2 | S17: 1 | U17: 1
A18: 8 | B18: Are there conflicts between the catch history and the CPUE response? | C18: Many conflicts for more than one period or for a period of more than 5 years | D18: Conflict for a short period ( 5 years) | E18: No conflicts | G18: 3 | I18: 3 | K18: 3 | M18: 3 | O18: 3 | Q18: 3 | S18: 3 | U18: 3
A19: 9 | B19: Is the interannual variability outside biologically plausible bounds (e.g. SCRS/2012/039) | C19: More than 50% of annual estimates are outside plausible bounds | D19: Between 50% and 10% of annual indices outside plausible bounds | E19: Less than 10% of the annual indices outside plausible bounds
A20: 10 | B20: Are there severe biologically implausible trends in relative abundance in part of the time series (e.g. SCRS/2012/039) | C20: Severe trend for a period of more than 4 years | D20: Severe trend for a short time period (4 or less years) | E20: No severe change | G20: 3 | I20: 3 | K20: 3 | M20: 3 | O20: 3 | Q20: 3 | S20: 3 | U20: 3
A21: 11 | B21: Assessment of data quality and adequacy of data for standardization purposes (e.g. sampling design, sample size, factors considered) | C21: Unbalanced data respect to standarization factors: numerous data points for each factor combination (90% of the cells have less than 10 observations eg. Aggregate data such as monthly cpue used for a model with quarterly time factors) | D21: Some lack of balance in data respect to standarization factors: numerous data points for each factor combination (More than 50% of the cells have less than 10 observations) | E21: Well balanced data respect to standarization factors: numerous data points for each factor combination (>10 observations for more than 90% of the factorial cells) | G21: 2 | I21: 2 | K21: 2 | M21: 2 | O21: 3 | Q21: 3 | S21: 3 | U21: 3
A22: 12 | B22: Is this CPUE time series continuous? | C22: Very Discontinuous more than two breaks in the time series | D22: one or two breaks in the time series | E22: Complete | G22: 3 | I22: 3 | K22: 3 | M22: 3 | O22: 2 | Q22: 2 | S22: 2 | U22: 3
A23: 13 | B23: Were discards included in the estimation of the CPUE? | C23: Discards not considered and discarding practices probably have changed through the time period of the index | D23: Discard not considered but discarding practices to have remained constant during the time period covered by the index | E23: Dead/live accounted for through observers or no discards exist during the time period of the index | G23: 2 | I23: 2 | K23: 2 | M23: 2 | O23: 2 | Q23: 2 | S23: 2 | U23: 2

Sheet MoroccoGN
A2: Year | B2: Std.CPUE | C2: Upper | D2: Lower | E2: CV
A3: 1999 | B3: 58.256 | C3: 102.013 | D3: 33.268 | E3: 0.075
A4: 2000 | B4: 66.671 | C4: 77.241 | D4: 57.547 | E4: 0.018
A5: 2001 | B5: 43.149 | C5: 48.919 | D5: 38.059 | E5: 0.018
A6: 2002 | B6: 56.034 | C6: 65.954 | D6: 47.606 | E6: 0.021
A7: 2003 | B7: 48.181 | C7: 55.014 | D7: 42.197 | E7: 0.018
A8: 2004 | B8: 58.411 | C8: 67.898 | D8: 50.25 | E8: 0.02
A9: 2005 | B9: 70.678 | C9: 80.264 | D9: 62.237 | E9: 0.016
A10: 2006 | B10: 66.164 | C10: 74.536 | D10: 58.731 | E10: 0.015
A11: 2007 | B11: 63.163 | C11: 70.715 | D11: 56.418 | E11: 0.014
A12: 2008 | B12: 69.178 | C12: 79.043 | D12: 60.545 | E12: 0.017
A13: 2009 | B13: 55.582 | C13: 64.302 | D13: 48.045 | E13: 0.019
A14: 2010 | B14: 51.887 | C14: 58.854 | D14: 45.746 | E14: 0.017
A15: 2011 | B15: 46.505 | C15: 66.888 | D15: 32.333 | E15: 0.051

Sheet SicilyGreece
A2: Year | B2: Ligurian LL | C2: Greek LL | D2: SIC LL
A3: 1987 | C3: 184.62
A4: 1988 | C4: 220.85
A5: 1989
A6: 1990 | C6: 202.21
A7: 1991 | B7: 88.467336 | C7: 273.55 | D7: 100.28498
A8: 1992 | B8: 66.100051 | C8: 105.92 | D8: 98.514928
A9: 1993 | B9: 68.763321 | C9: 186.92
A10: 1994 | B10: 90.595943 | C10: 238.65 | D10: 99.454398
A11: 1995 | B11: 94.617415 | C11: 156.12 | D11: 124.19214
A12: 1996 | B12: 94.344342
A13: 1997 | B13: 101.06904 | D13: 75.917216
A14: 1998 | B14: 144.93701 | C14: 227.28 | D14: 127.62963
A15: 1999 | B15: 101.89597 | C15: 157.7 | D15: 151.49775
A16: 2000 | B16: 134.68065 | C16: 112.5 | D16: 93.349615
A17: 2001 | B17: 181.62454 | C17: 117.49 | D17: 143.95968
A18: 2002 | B18: 140.32481 | C18: 95.68 | D18: 204.83786
A19: 2003 | B19: 152.27809 | C19: 115.3 | D19: 82.223803
A20: 2004 | B20: 98.857786 | C20: 115.75 | D20: 111.18542
A21: 2005 | B21: 80.801294 | C21: 114.65 | D21: 123.21227
A22: 2006 | B22: 125.04794 | C22: 123.44 | D22: 140.62136
A23: 2007 | B23: 239.99924 | C23: 127.24 | D23: 81.060357
A24: 2008 | B24: 208.17563 | C24: 122.51 | D24: 86.951489
A25: 2009 | B25: 123.38733 | C25: 104.48 | D25: 99.118032
A26: 2010 | C26: 126.8
A27: 2011 | C27: 99.11
A28: 2012 | C28: 97.5
A29: 2013 | C29: 149.78
A30: 2014 | C30: 115.06
A31: 2015 | C31: 96.55

Sheet Spanish LL
A1: originally calculated as n/1000 hooks
B2: standardized values in weight calculated as the product of standardized CPUE in number times the average weight of fish for each year
A4: year | B4: CPUEn
A5: 1988 | B5: 2.48
A6: 1989 | B6: 1.43
A7: 1990 | B7: 1.56
A8: 1991 | B8: 2.02
A9: 1992 | B9: 2.13
A10: 1993 | B10: 2.12
A11: 1994 | B11: 2.36
A12: 1995 | B12: 2.2
A13: 1996 | B13: 1.82
A14: 1997 | B14: 1.78
A15: 1998 | B15: 1.98
A16: 1999 | B16: 1.73
... A32: 2015 | B32: 1.93
A34: mean | B34: =AVERAGE(B5:B30) -> 1.94

Sheet MoroccoLL
A1: Year | B1: Std.cpue
A2: 2001 | B2: 26.4668
A3: 2002 | B3: 31.8979
A4: 2003 | B4: 36.0351
A5: 2004 | B5: 38.6269
A6: 2005 | B6: 30.4991
A7: 2006 | B7: 43.9984
A8: 2007 | B8: 41.2178
A9: 2008 | B9: 33.106
A10: 2009 | B10: 34.469
A11: 2010 | B11: 34.5673
A12: 2011 | B12: 40.1586
A13: 2012 | B13: 72.7279
... A16: 2015 | B16: 67.2613
