Workbook

Sheet estDD
C1: From Mauricio | D1: EstimUndersizeSWO.xlsx
D2: DiscardsEstim
D3: cellsBA78:BP88
D4: Estimated by Secretariat | E4: Task1DD | F4: Estimated by Spain | G4: Task1DD | H4: Estimated by Secretariat | I4: =+G4 -> Task1DD | J4: =+H4 -> Estimated by Secretariat | K4: =+I4 -> Task1DD | L4: =+J4 -> Estimated by Secretariat | M4: =+K4 -> Task1DD | N4: =+L4 -> Estimated by Secretariat | O4: =+M4 -> Task1DD | P4: =+N4 -> Estimated by Secretariat | ... AC4: =+AA4 -> Task1DD
C5: YearC | D5: EU-Italy | E5: EU-Italy | F5: EU-España | G5: EU-España | H5: EU-Greece | I5: EU-Greece | J5: Maroc | K5: Maroc | L5: Tunisie | M5: Tunisie | N5: Algerie | O5: Algerie | P5: EU-Malta | Q5: EU-Malta | R5: Türkiye | S5: Türkiye | T5: EU-Cyprus | U5: EU-Cyprus | V5: Libya | W5: Libya | X5: EU-France | Y5: EU-France | Z5: EU-Croatia | AA5: EU-Croatia | AB5: Egypt | AC5: Egypt
C6: 2014 | D6: 0 | E6: 537.86407 | F6: 0 | H6: 153.33526 | J6: 0 | K6: 197.88937 | L6: 0 | M6: 271.88983 | N6: 0 | O6: 144.83017 | P6: 43.409077 | R6: 0 | S6: 15.77152 | T6: 6.7466397 | V6: 0 | X6: 13.721569 | Z6: 1.4328404 | AB6: 0.04173973
C7: 2015 | D7: 0 | E7: 669.76264 | F7: 35.340019 | G7: 6.709 | H7: 86.794321 | J7: 0 | K7: 123.46241 | L7: 0 | M7: 272.94571 | N7: 0 | O7: 147.27955 | P7: 56.420347 | R7: 0 | S7: 9.88197 | T7: 5.1592898 | V7: 67.08171 | W7: 0 | X7: 20.585001 | Z7: 0.59793417 | AB7: 0
C8: 2016 | D8: 0 | E8: 622.66891 | F8: 16.04396 | H8: 86.804704 | J8: 0 | K8: 285.26909 | L8: 0 | M8: 265.82167 | N8: 0 | O8: 175.75011 | P8: 47.235715 | R8: 0 | S8: 19.78377 | T8: 4.9768953 | V8: 110.08281 | X8: 19.80876 | Z8: 2.4059294 | AB8: 0
C9: 2017 | D9: 0 | E9: 907.38449 | F9: 96.415303 | H9: 127.78784 | J9: 0 | K9: 350.2629 | L9: 0 | M9: 374.29801 | N9: 0 | O9: 205.26372 | P9: 136.41963 | R9: 0 | S9: 151.15247 | T9: 19.763193 | V9: 11.634578 | X9: 43.799501 | Z9: 6.6463354 | AB9: 0
C10: 2018 | D10: 0 | E10: 534.95601 | F10: 95.021807 | G10: 83.5295 | H10: 114.18344 | J10: 0 | K10: 354.81632 | L10: 0 | M10: 363.50338 | N10: 0 | O10: 197.05317 | P10: 127.03471 | R10: 0 | S10: 147.97723 | T10: 18.10082 | V10: 27.147349 | W10: 0 | X10: 33.882464 | Z10: 10.744459 | AB10: 1.5512771
C11: 2019 | D11: 1000.8074 | F11: 46.771403 | G11: 89.39109 | H11: 242.85586 | J11: 406.3437 | K11: 0 | L11: 385.69009 | N11: 200.6926 | P11: 167.98202 | R11: 159.74223 | T11: 9.5913188 | V11: 10.083301 | W11: 0 | X11: 28.03057 | Z11: 12.601098 | AB11: 0
C12: 2020 | D12: 907.41009 | F12: 145.20125 | H12: 214.25726 | J12: 393.41198 | K12: 0 | L12: 379.04994 | N12: 194.27806 | O12: 0 | P12: 149.1825 | R12: 155.53087 | T12: 11.923901 | U12: 0.351 | V12: 8.532024 | W12: 0 | X12: 42.408642 | Z12: 9.2247687 | AA12: 0.026 | AB12: 1.5512771
C13: 2021 | D13: 812.70251 | F13: 87.097877 | G13: 187.96349 | H13: 223.52681 | J13: 382.3253 | K13: 0 | L13: 367.79307 | N13: 172.87044 | P13: 161.49166 | R13: 147.61698 | T13: 22.192202 | V13: 7.3685662 | W13: 0 | X13: 37.057131 | Z13: 9.7333793 | AA13: 0.009 | AB13: 2.7147349
C14: 2022 | D14: 828.88551 | F14: 249.16248 | G14: 90 | H14: 120.84967 | J14: 368.53312 | K14: 0 | L14: 353.9871 | N14: 182.96654 | P14: 157.09803 | R14: 126.50638 | T14: 14.43222 | U14: 0.02 | V14: 8.1442047 | W14: 0 | X14: 24.367471 | Y14: 0 | Z14: 14.992377 | AA14: 0.221 | AB14: 10.083301 | AC14: 0
C15: 2023 | D15: 934.30639 | F15: 187.42704 | G15: 107.236 | H15: 144.79238 | J15: 370.85388 | L15: 302.77952 | N15: 182.95374 | P15: 148.52192 | R15: 142.18523 | T15: 22.862144 | U15: 0.232 | V15: 96.954818 | X15: 25.960529 | Y15: 0 | Z15: 15.78692 | AA15: 1.251 | AB15: 28.310807
C16: 2024 | D16: 1246.9395 | F16: 125.84002 | G16: 66.844 | H16: 163.34643 | J16: 370.85388 | K16: 0 | L16: 329.74244 | N16: 183.16704 | P16: 154.44109 | R16: 142.51618 | T16: 24.467403 | U16: 0.3882 | V16: 46.538313 | X16: 30.499916 | Y16: 0.088 | Z16: 15.491497 | AA16: 0.554 | AB16: 38.781927 | AC16: 0
G18: New Estimates by Spain has much smaller than the original Task1DD by Spain… Use the new values | U18: CPC provided DD but very small compared to the estimated by the Secretariat, ignore the submitted T1DD and use the esimated values by the Secretariat
A23: Note for AK
C24: 0 | D24: based on Task1DD
C25: 1 | D25: Delete T1DD after 2014 for LL: | E25: EU-España | F25: because Spain provided the new estimates
C26: 2 | D26: Delete T1DD after 2014 for LL: | E26: EU-Cyprus | F26: Libya | G26: EU-France | H26: EU-Croatia | I26: Egypt | J26: because those CPC provided a very small values compared to the estimated values by the Secretariat
C27: 3 | D27: Delete T1DD in 2020 for LL: | E27: Algerie | F27: zero but for AK calculation
C28: 4 | D28: add the estimates of DD by the secretariat (LL)
C31: YearC | D31: estDD | E31: FlagName
C32: 2014 | D32: 0 | E32: EU-Italy
C33: 2015 | D33: 0 | E33: EU-Italy
C34: 2016 | D34: 0 | E34: EU-Italy
C35: 2017 | D35: 0 | E35: EU-Italy
C36: 2018 | D36: 0 | E36: EU-Italy
C37: 2019 | D37: 1000.8074 | E37: EU-Italy
C38: 2020 | D38: 907.41009 | E38: EU-Italy
C39: 2021 | D39: 812.70251 | E39: EU-Italy
C40: 2022 | D40: 828.88551 | E40: EU-Italy
C41: 2023 | D41: 934.30639 | E41: EU-Italy
C42: 2024 | D42: 1246.9395 | E42: EU-Italy
C43: 2014 | D43: 0 | E43: EU-España
... C174: 2024 | D174: 38.781927 | E174: Egypt

Sheet manual_check
B1: OK! | J1: OK!
A2: SWOMed_JABBA_catch_10April2026.csv | F2: include other gear | M2: SWOMed_t1MedFlag_10April2026.csv | T2: estDD | X2: remove | Y2: (blank)
A3: Year | B3: Catch | E3: Year | F3: DD | G3: L | H3: estDD | I3: sum | J3: check | M3: Year | N3: FlagName | O3: GearGrp | P3: CatchType | Q3: Catch | R3: remove | T3: =+estDD!C31 -> YearC | U3: =+estDD!D31 -> estDD | V3: =+estDD!E31 -> FlagName
A4: 1950 | B4: 586 | E4: 1950 | G4: 586 | I4: =+SUM(F4:H4) -> 586 | J4: =+IF(B4=I4,0,B4-I4) -> 0 | M4: 2022 | N4: EU-France | O4: GN | P4: DD | Q4: 0 | T4: =+estDD!C32 -> 2014 | U4: =+estDD!D32 -> 0 | V4: =+estDD!E32 -> EU-Italy | X4: Sum of Catch | Y4: Column Labels | AE4: Row Labels | AF4: Sum of estDD
A5: 1951 | B5: 580 | E5: 1951 | G5: 580 | I5: =+SUM(F5:H5) -> 580 | J5: =+IF(B5=I5,0,B5-I5) -> 0 | M5: 2023 | N5: EU-France | O5: GN | P5: DD | Q5: 0 | T5: =+estDD!C33 -> 2015 | U5: =+estDD!D33 -> 0 | V5: =+estDD!E33 -> EU-Italy | X5: Row Labels | Y5: DD | Z5: L | AA5: Grand Total | AE5: 2014 | AF5: 218.68713
A6: 1952 | B6: 337 | E6: 1952 | G6: 337 | I6: =+SUM(F6:H6) -> 337 | J6: =+IF(B6=I6,0,B6-I6) -> 0 | M6: 2024 | N6: EU-France | O6: GN | P6: DD | Q6: 0 | T6: =+estDD!C34 -> 2016 | U6: =+estDD!D34 -> 0 | V6: =+estDD!E34 -> EU-Italy | X6: 1950 | Z6: 586 | AA6: 586 | AE6: 2015 | AF6: 271.97862
A7: 1953 | B7: 501 | E7: 1953 | G7: 501 | I7: =+SUM(F7:H7) -> 501 | J7: =+IF(B7=I7,0,B7-I7) -> 0 | M7: 2014 | N7: Maroc | O7: GN | P7: DD | Q7: 0 | T7: =+estDD!C35 -> 2017 | U7: =+estDD!D35 -> 0 | V7: =+estDD!E35 -> EU-Italy | X7: 1951 | Z7: 580 | AA7: 580 | AE7: 2016 | AF7: 287.35877
A8: 1954 | B8: 452 | E8: 1954 | G8: 452 | I8: =+SUM(F8:H8) -> 452 | J8: =+IF(B8=I8,0,B8-I8) -> 0 | M8: 2022 | N8: EU-France | O8: HL | P8: DD | Q8: 0 | T8: =+estDD!C36 -> 2018 | U8: =+estDD!D36 -> 0 | V8: =+estDD!E36 -> EU-Italy | X8: 1952 | Z8: 337 | AA8: 337 | AE8: 2017 | AF8: 442.46639
A9: 1955 | B9: 340 | E9: 1955 | G9: 340 | I9: =+SUM(F9:H9) -> 340 | J9: =+IF(B9=I9,0,B9-I9) -> 0 | M9: 2023 | N9: EU-France | O9: HL | P9: DD | Q9: 0.035 | T9: =+estDD!C37 -> 2019 | U9: =+estDD!D37 -> 1000.8074 | V9: =+estDD!E37 -> EU-Italy | X9: 1953 | Z9: 501 | AA9: 501 | AE9: 2018 | AF9: 427.66633
A10: 1956 | B10: 393 | E10: 1956 | G10: 393 | I10: =+SUM(F10:H10) -> 393 | J10: =+IF(B10=I10,0,B10-I10) -> 0 | M10: 2024 | N10: EU-France | O10: HL | P10: DD | Q10: 0 | T10: =+estDD!C38 -> 2020 | U10: =+estDD!D38 -> 907.41009 | V10: =+estDD!E38 -> EU-Italy | X10: 1954 | Z10: 452 | AA10: 452 | AE10: 2019 | AF10: 2671.1916
A11: 1957 | B11: 645.4 | E11: 1957 | G11: 645.4 | I11: =+SUM(F11:H11) -> 645.4 | J11: =+IF(B11=I11,0,B11-I11) -> 0 | M11: 2014 | N11: Maroc | O11: HL | P11: DD | Q11: 0 | T11: =+estDD!C39 -> 2021 | U11: =+estDD!D39 -> 812.70251 | V11: =+estDD!E39 -> EU-Italy | X11: 1955 | Z11: 340 | AA11: 340 | AE11: 2020 | AF11: 2611.9626
A12: 1958 | B12: 914 | E12: 1958 | G12: 914 | I12: =+SUM(F12:H12) -> 914 | J12: =+IF(B12=I12,0,B12-I12) -> 0 | M12: 2011 | N12: EU-España | O12: LL | P12: DD | Q12: 0 | T12: =+estDD!C40 -> 2022 | U12: =+estDD!D40 -> 828.88551 | V12: =+estDD!E40 -> EU-Italy | X12: 1956 | Z12: 393 | AA12: 393 | AE12: 2021 | AF12: 2434.4907
A13: 1959 | B13: 600.667 | E13: 1959 | G13: 600.667 | I13: =+SUM(F13:H13) -> 600.667 | J13: =+IF(B13=I13,0,B13-I13) -> 0 | M13: 2015 | N13: EU-España | O13: LL | P13: DD | Q13: 6.709 | R13: 1 | T13: =+estDD!C41 -> 2023 | U13: =+estDD!D41 -> 934.30639 | V13: =+estDD!E41 -> EU-Italy | X13: 1957 | Z13: 645.4 | AA13: 645.4 | AE13: 2022 | AF13: 2460.0084
A14: 1960 | B14: 515.222 | E14: 1960 | G14: 515.222 | I14: =+SUM(F14:H14) -> 515.222 | J14: =+IF(B14=I14,0,B14-I14) -> 0 | M14: 2018 | N14: EU-España | O14: LL | P14: DD | Q14: 83.5295 | R14: 1 | T14: =+estDD!C42 -> 2024 | U14: =+estDD!D42 -> 1246.9395 | V14: =+estDD!E42 -> EU-Italy | X14: 1958 | Z14: 914 | AA14: 914 | AE14: 2023 | AF14: 2603.6953
A15: 1961 | B15: 611.963 | E15: 1961 | G15: 611.963 | I15: =+SUM(F15:H15) -> 611.963 | J15: =+IF(B15=I15,0,B15-I15) -> 0 | M15: 2019 | N15: EU-España | O15: LL | P15: DD | Q15: 89.39109 | R15: 1 | T15: =+estDD!C43 -> 2014 | U15: =+estDD!D43 -> 0 | V15: =+estDD!E43 -> EU-España | X15: 1959 | Z15: 600.667 | AA15: 600.667 | AE15: 2024 | AF15: 2872.6256
A16: 1962 | B16: 703.284 | E16: 1962 | G16: 703.284 | I16: =+SUM(F16:H16) -> 703.284 | J16: =+IF(B16=I16,0,B16-I16) -> 0 | M16: 2021 | N16: EU-España | O16: LL | P16: DD | Q16: 187.96349 | R16: 1 | T16: =+estDD!C44 -> 2015 | U16: =+estDD!D44 -> 35.340019 | V16: =+estDD!E44 -> EU-España | X16: 1960 | Z16: 515.222 | AA16: 515.222 | AE16: Grand Total | AF16: 17302.131
A17: 1963 | B17: 722.156 | E17: 1963 | G17: 722.156 | I17: =+SUM(F17:H17) -> 722.156 | J17: =+IF(B17=I17,0,B17-I17) -> 0 | M17: 2022 | N17: EU-España | O17: LL | P17: DD | Q17: 90 | R17: 1 | T17: =+estDD!C45 -> 2016 | U17: =+estDD!D45 -> 16.04396 | V17: =+estDD!E45 -> EU-España | X17: 1961 | Z17: 611.963 | AA17: 611.963
A18: 1964 | B18: 798.468 | E18: 1964 | G18: 798.468 | I18: =+SUM(F18:H18) -> 798.468 | J18: =+IF(B18=I18,0,B18-I18) -> 0 | M18: 2023 | N18: EU-España | O18: LL | P18: DD | Q18: 107.236 | R18: 1 | T18: =+estDD!C46 -> 2017 | U18: =+estDD!D46 -> 96.415303 | V18: =+estDD!E46 -> EU-España | X18: 1962 | Z18: 703.284 | AA18: 703.284
A19: 1965 | B19: 1760 | E19: 1965 | G19: 1760 | I19: =+SUM(F19:H19) -> 1760 | J19: =+IF(B19=I19,0,B19-I19) -> 0 | M19: 2024 | N19: EU-España | O19: LL | P19: DD | Q19: 66.844 | R19: 1 | T19: =+estDD!C47 -> 2018 | U19: =+estDD!D47 -> 95.021807 | V19: =+estDD!E47 -> EU-España | X19: 1963 | Z19: 722.156 | AA19: 722.156
A20: 1966 | B20: 1752 | E20: 1966 | G20: 1752 | I20: =+SUM(F20:H20) -> 1752 | J20: =+IF(B20=I20,0,B20-I20) -> 0 | M20: 2008 | N20: Türkiye | O20: LL | P20: DD | Q20: 55.42489 | T20: =+estDD!C48 -> 2019 | U20: =+estDD!D48 -> 46.771403 | V20: =+estDD!E48 -> EU-España | X20: 1964 | Z20: 798.468 | AA20: 798.468
A21: 1967 | B21: 1317 | E21: 1967 | G21: 1317 | I21: =+SUM(F21:H21) -> 1317 | J21: =+IF(B21=I21,0,B21-I21) -> 0 | M21: 2009 | N21: Türkiye | O21: LL | P21: DD | Q21: 43.21993 | T21: =+estDD!C49 -> 2020 | U21: =+estDD!D49 -> 145.20125 | V21: =+estDD!E49 -> EU-España | X21: 1965 | Z21: 1760 | AA21: 1760
A22: 1968 | B22: 3440 | E22: 1968 | G22: 3440 | I22: =+SUM(F22:H22) -> 3440 | J22: =+IF(B22=I22,0,B22-I22) -> 0 | M22: 2010 | N22: Türkiye | O22: LL | P22: DD | Q22: 47.95833 | T22: =+estDD!C50 -> 2021 | U22: =+estDD!D50 -> 87.097877 | V22: =+estDD!E50 -> EU-España | X22: 1966 | Z22: 1752 | AA22: 1752
A23: 1969 | B23: 3723 | E23: 1969 | G23: 3723 | I23: =+SUM(F23:H23) -> 3723 | J23: =+IF(B23=I23,0,B23-I23) -> 0 | M23: 2011 | N23: Türkiye | O23: LL | P23: DD | Q23: 27.22425 | T23: =+estDD!C51 -> 2022 | U23: =+estDD!D51 -> 249.16248 | V23: =+estDD!E51 -> EU-España | X23: 1967 | Z23: 1317 | AA23: 1317
A24: 1970 | B24: 3341 | E24: 1970 | G24: 3341 | I24: =+SUM(F24:H24) -> 3341 | J24: =+IF(B24=I24,0,B24-I24) -> 0 | M24: 2012 | N24: Türkiye | O24: LL | P24: DD | Q24: 9.5483 | T24: =+estDD!C52 -> 2023 | U24: =+estDD!D52 -> 187.42704 | V24: =+estDD!E52 -> EU-España | X24: 1968 | Z24: 3440 | AA24: 3440
A25: 1971 | B25: 4975 | E25: 1971 | G25: 4975 | I25: =+SUM(F25:H25) -> 4975 | J25: =+IF(B25=I25,0,B25-I25) -> 0 | M25: 2013 | N25: Türkiye | O25: LL | P25: DD | Q25: 13.8993 | T25: =+estDD!C53 -> 2024 | U25: =+estDD!D53 -> 125.84002 | V25: =+estDD!E53 -> EU-España | X25: 1969 | Z25: 3723 | AA25: 3723
A26: 1972 | B26: 11160.407 | E26: 1972 | G26: 11160.407 | I26: =+SUM(F26:H26) -> 11160.407 | J26: =+IF(B26=I26,0,B26-I26) -> 0 | M26: 2014 | N26: Türkiye | O26: LL | P26: DD | Q26: 15.77152 | T26: =+estDD!C54 -> 2014 | U26: =+estDD!D54 -> 153.33526 | V26: =+estDD!E54 -> EU-Greece | X26: 1970 | Z26: 3341 | AA26: 3341
A27: 1973 | B27: 8734.536 | E27: 1973 | G27: 8734.536 | I27: =+SUM(F27:H27) -> 8734.536 | J27: =+IF(B27=I27,0,B27-I27) -> 0 | M27: 2015 | N27: Türkiye | O27: LL | P27: DD | Q27: 9.88197 | T27: =+estDD!C55 -> 2015 | U27: =+estDD!D55 -> 86.794321 | V27: =+estDD!E55 -> EU-Greece | X27: 1971 | Z27: 4975 | AA27: 4975
A28: 1974 | B28: 9712.6294 | E28: 1974 | G28: 9712.6294 | I28: =+SUM(F28:H28) -> 9712.6294 | J28: =+IF(B28=I28,0,B28-I28) -> 0 | M28: 2016 | N28: Türkiye | O28: LL | P28: DD | Q28: 19.78377 | T28: =+estDD!C56 -> 2016 | U28: =+estDD!D56 -> 86.804704 | V28: =+estDD!E56 -> EU-Greece | X28: 1972 | Z28: 11160.407 | AA28: 11160.407
A29: 1975 | B29: 8522.3613 | E29: 1975 | G29: 8522.3613 | I29: =+SUM(F29:H29) -> 8522.3613 | J29: =+IF(B29=I29,0,B29-I29) -> 0 | M29: 2017 | N29: Türkiye | O29: LL | P29: DD | Q29: 151.15247 | T29: =+estDD!C57 -> 2017 | U29: =+estDD!D57 -> 127.78784 | V29: =+estDD!E57 -> EU-Greece | X29: 1973 | Z29: 8734.536 | AA29: 8734.536
A30: 1976 | B30: 9544.1429 | E30: 1976 | G30: 9544.1429 | I30: =+SUM(F30:H30) -> 9544.1429 | J30: =+IF(B30=I30,0,B30-I30) -> 0 | M30: 2018 | N30: Türkiye | O30: LL | P30: DD | Q30: 147.97723 | T30: =+estDD!C58 -> 2018 | U30: =+estDD!D58 -> 114.18344 | V30: =+estDD!E58 -> EU-Greece | X30: 1974 | Z30: 9712.6294 | AA30: 9712.6294
A31: 1977 | B31: 10046.048 | E31: 1977 | G31: 10046.048 | I31: =+SUM(F31:H31) -> 10046.048 | J31: =+IF(B31=I31,0,B31-I31) -> 0 | M31: 2008 | N31: Algerie | O31: LL | P31: DD | Q31: 175.24804 | T31: =+estDD!C59 -> 2019 | U31: =+estDD!D59 -> 242.85586 | V31: =+estDD!E59 -> EU-Greece | X31: 1975 | Z31: 8522.3613 | AA31: 8522.3613
... A41: 1987 | B41: 18319.979 | E41: 1987 | G41: 18319.979 | I41: =+SUM(F41:H41) -> 18319.979 | J41: =+IF(B41=I41,0,B41-I41) -> 0 | M41: 2018 | N41: Algerie | O41: LL | P41: DD | Q41: 197.05317 | T41: =+estDD!C69 -> 2018 | U41: =+estDD!D69 -> 0 | V41: =+estDD!E69 -> Maroc | X41: 1985 | Z41: 15293.964 | AA41: 15293.964
A42: 1988 | B42: 20365.376 | E42: 1988 | G42: 20365.376 | I42: =+SUM(F42:H42) -> 20365.376 | J42: =+IF(B42=I42,0,B42-I42) -> 0 | M42: 2020 | N42: Algerie | O42: LL | P42: DD | Q42: 0 | R42: 1 | T42: =+estDD!C70 -> 2019 | U42: =+estDD!D70 -> 406.3437 | V42: =+estDD!E70 -> Maroc | X42: 1986 | Z42: 16764.86 | AA42: 16764.86
A43: 1989 | B43: 17761.891 | E43: 1989 | G43: 17761.891 | I43: =+SUM(F43:H43) -> 17761.891 | J43: =+IF(B43=I43,0,B43-I43) -> 0 | M43: 2011 | N43: Chinese Taipei | O43: LL | P43: DD | Q43: 0 | T43: =+estDD!C71 -> 2020 | U43: =+estDD!D71 -> 393.41198 | V43: =+estDD!E71 -> Maroc | X43: 1987 | Z43: 18319.979 | AA43: 18319.979
A44: 1990 | B44: 16017.504 | E44: 1990 | G44: 16017.504 | I44: =+SUM(F44:H44) -> 16017.504 | J44: =+IF(B44=I44,0,B44-I44) -> 0 | M44: 2012 | N44: Chinese Taipei | O44: LL | P44: DD | Q44: 0 | T44: =+estDD!C72 -> 2021 | U44: =+estDD!D72 -> 382.3253 | V44: =+estDD!E72 -> Maroc | X44: 1988 | Z44: 20365.376 | AA44: 20365.376
A45: 1991 | B45: 15746.277 | E45: 1991 | G45: 15746.277 | I45: =+SUM(F45:H45) -> 15746.277 | J45: =+IF(B45=I45,0,B45-I45) -> 0 | M45: 2013 | N45: Chinese Taipei | O45: LL | P45: DD | Q45: 0 | T45: =+estDD!C73 -> 2022 | U45: =+estDD!D73 -> 368.53312 | V45: =+estDD!E73 -> Maroc | X45: 1989 | Z45: 17761.891 | AA45: 17761.891
A46: 1992 | B46: 14709.419 | E46: 1992 | G46: 14709.419 | I46: =+SUM(F46:H46) -> 14709.419 | J46: =+IF(B46=I46,0,B46-I46) -> 0 | M46: 2014 | N46: Chinese Taipei | O46: LL | P46: DD | Q46: 0 | T46: =+estDD!C74 -> 2023 | U46: =+estDD!D74 -> 370.85388 | V46: =+estDD!E74 -> Maroc | X46: 1990 | Z46: 16017.504 | AA46: 16017.504
A47: 1993 | B47: 13264.866 | E47: 1993 | G47: 13264.866 | I47: =+SUM(F47:H47) -> 13264.866 | J47: =+IF(B47=I47,0,B47-I47) -> 0 | M47: 2016 | N47: Chinese Taipei | O47: LL | P47: DD | Q47: 0 | T47: =+estDD!C75 -> 2024 | U47: =+estDD!D75 -> 370.85388 | V47: =+estDD!E75 -> Maroc | X47: 1991 | Z47: 15746.277 | AA47: 15746.277
A48: 1994 | B48: 16082.214 | E48: 1994 | G48: 16082.214 | I48: =+SUM(F48:H48) -> 16082.214 | J48: =+IF(B48=I48,0,B48-I48) -> 0 | M48: 2017 | N48: Chinese Taipei | O48: LL | P48: DD | Q48: 0 | T48: =+estDD!C76 -> 2014 | U48: =+estDD!D76 -> 0 | V48: =+estDD!E76 -> Tunisie | X48: 1992 | Z48: 14709.419 | AA48: 14709.419
A49: 1995 | B49: 13015.475 | E49: 1995 | G49: 13015.475 | I49: =+SUM(F49:H49) -> 13015.475 | J49: =+IF(B49=I49,0,B49-I49) -> 0 | M49: 2018 | N49: Chinese Taipei | O49: LL | P49: DD | Q49: 0 | T49: =+estDD!C77 -> 2015 | U49: =+estDD!D77 -> 0 | V49: =+estDD!E77 -> Tunisie | X49: 1993 | Z49: 13264.866 | AA49: 13264.866
...
